Workbook
Name equalisation_month: Settings!$B$8
Name fact_months: Settings!$B$7

Sheet Settings
A1: Model settings
A2: Payroll budget plan vs actual. Synthetic data, illustration of method. Comp Budget Lab.
A4: Only the green cells are meant to be edited. Everything else recalculates.
A6: Name | B6: Value | C6: What it is | D6: Notes
A7: fact_months | B7: 8 | C7: Months of actuals | D7: Months are numbered from 1 for January, so 8 means actuals run to August. Later months are forecast.
A8: equalisation_month | B8: 9 | C8: Equalisation starts in month | D8: Months are numbered from 1 for January, so 9 means September. From that month onwards the forecast carries the cost of closing the pay gap.
A11: Scenario
A12: Full equalisation: every unexplained residual brought to zero. The budget was approved before that decision was taken, so it contains no money for it. From the equalisation month onwards the forecast therefore runs above plan.

Sheet Equalisation
A1: Cost of closing the pay gap, by department
A2: What it costs to raise pay for the people who are underpaid for reasons that grade and tenure do not explain. Each figure is the annual cost of those raises plus the employer contributions due on them. The monthly uplift is that annual cost divided by twelve.
A4: The figures come from a separate calculator that measures the gap and prices the two ways of closing it: bringing every category to a 5% threshold, or bringing every unexplained difference to zero. This workbook takes its output and asks a different question: what that decision does to a budget already approved. Calculator and method: https://olgadimitrovagit.github.io/comp-budget-lab/
A7: Department | B7: Recipients | C7: Adjustment, EUR | D7: Contributions, EUR | E7: Annual cost, EUR | F7: Monthly uplift, EUR | G7: Run-rate deviation, %
A8: Engineering | B8: 8 | C8: 77733.194 | D8: 20286.974 | E8: =C8+D8 -> 98020.169 | F8: =E8/12 -> 8168.3474 | G8: -1.4409977
A9: Sales | B9: 7 | C9: 124991.43 | D9: 4866.7997 | E9: =C9+D9 -> 129858.23 | F9: =E9/12 -> 10821.519 | G9: 9.2535006
A10: Operations | B10: 12 | C10: 16228.187 | D10: 5111.8788 | E10: =C10+D10 -> 21340.065 | F10: =E10/12 -> 1778.3388 | G10: 1.3274111
A11: Manufacturing | B11: 12 | C11: 65975.976 | D11: 20782.432 | E11: =C11+D11 -> 86758.409 | F11: =E11/12 -> 7229.8674 | G11: 2.3558405
A12: Marketing | B12: 0 | C12: 0 | D12: 0 | E12: =C12+D12 -> 0 | F12: =E12/12 -> 0 | G12: 2.4329917
A13: Customer Support | B13: 10 | C13: 31975.109 | D13: 10072.159 | E13: =C13+D13 -> 42047.269 | F13: =E13/12 -> 3503.9391 | G13: 2.1339525
A14: Legal | B14: 3 | C14: 18287.126 | D14: 210.30195 | E14: =C14+D14 -> 18497.428 | F14: =E14/12 -> 1541.4523 | G14: 2.6526178
A15: TOTAL | B15: =SUM(B8:B14) -> 52 | C15: =SUM(C8:C14) -> 335191.02 | D15: =SUM(D8:D14) -> 61330.547 | E15: =SUM(E8:E14) -> 396521.57 | F15: =SUM(F8:F14) -> 33043.464

Sheet Data
A1: Plan vs actual by department and month
A2: Yellow: from the CSV. Blue: calculated here. Deviation is actual (or forecast) minus plan: positive means overspend.
A4: Department | B4: Month | C4: # | D4: Plan, EUR | E4: Actual, EUR | F4: Forecast, EUR | G4: Expected, EUR | H4: Deviation, EUR | I4: Deviation, % | J4: Cumulative, EUR
A5: Engineering | B5: Jan | C5: 1 | D5: 344874.17 | E5: 339482.19 | F5: =IF(C5<=fact_months,"",ROUND(D5*(1+Equalisation!$G$8/100)+IF(C5>=equalisation_month,Equalisation!$F$8,0),2)) | G5: =IF(C5<=fact_months,E5,F5) -> 339482.19 | H5: =G5-D5 -> -5391.98 | I5: =IF(D5=0,"",H5/D5) -> -0.01563463 | J5: =H5 -> -5391.98
A6: Engineering | B6: Feb | C6: 2 | D6: 343877.42 | E6: 338599.58 | F6: =IF(C6<=fact_months,"",ROUND(D6*(1+Equalisation!$G$8/100)+IF(C6>=equalisation_month,Equalisation!$F$8,0),2)) | G6: =IF(C6<=fact_months,E6,F6) -> 338599.58 | H6: =G6-D6 -> -5277.84 | I6: =IF(D6=0,"",H6/D6) -> -0.015348027 | J6: =J5+H6 -> -10669.82
A7: Engineering | B7: Mar | C7: 3 | D7: 339558.19 | E7: 334287.48 | F7: =IF(C7<=fact_months,"",ROUND(D7*(1+Equalisation!$G$8/100)+IF(C7>=equalisation_month,Equalisation!$F$8,0),2)) | G7: =IF(C7<=fact_months,E7,F7) -> 334287.48 | H7: =G7-D7 -> -5270.71 | I7: =IF(D7=0,"",H7/D7) -> -0.015522258 | J7: =J6+H7 -> -15940.53
A8: Engineering | B8: Apr | C8: 4 | D8: 333909.96 | E8: 329292.71 | F8: =IF(C8<=fact_months,"",ROUND(D8*(1+Equalisation!$G$8/100)+IF(C8>=equalisation_month,Equalisation!$F$8,0),2)) | G8: =IF(C8<=fact_months,E8,F8) -> 329292.71 | H8: =G8-D8 -> -4617.25 | I8: =IF(D8=0,"",H8/D8) -> -0.01382783 | J8: =J7+H8 -> -20557.78
A9: Engineering | B9: May | C9: 5 | D9: 327597.23 | E9: 323163.6 | F9: =IF(C9<=fact_months,"",ROUND(D9*(1+Equalisation!$G$8/100)+IF(C9>=equalisation_month,Equalisation!$F$8,0),2)) | G9: =IF(C9<=fact_months,E9,F9) -> 323163.6 | H9: =G9-D9 -> -4433.63 | I9: =IF(D9=0,"",H9/D9) -> -0.013533784 | J9: =J8+H9 -> -24991.41
A10: Engineering | B10: Jun | C10: 6 | D10: 321616.76 | E10: 316851.64 | F10: =IF(C10<=fact_months,"",ROUND(D10*(1+Equalisation!$G$8/100)+IF(C10>=equalisation_month,Equalisation!$F$8,0),2)) | G10: =IF(C10<=fact_months,E10,F10) -> 316851.64 | H10: =G10-D10 -> -4765.12 | I10: =IF(D10=0,"",H10/D10) -> -0.014816143 | J10: =J9+H10 -> -29756.53
A11: Engineering | B11: Jul | C11: 7 | D11: 319623.26 | E11: 314626.4 | F11: =IF(C11<=fact_months,"",ROUND(D11*(1+Equalisation!$G$8/100)+IF(C11>=equalisation_month,Equalisation!$F$8,0),2)) | G11: =IF(C11<=fact_months,E11,F11) -> 314626.4 | H11: =G11-D11 -> -4996.86 | I11: =IF(D11=0,"",H11/D11) -> -0.015633593 | J11: =J10+H11 -> -34753.39
A12: Engineering | B12: Aug | C12: 8 | D12: 320287.76 | E12: 315905.42 | F12: =IF(C12<=fact_months,"",ROUND(D12*(1+Equalisation!$G$8/100)+IF(C12>=equalisation_month,Equalisation!$F$8,0),2)) | G12: =IF(C12<=fact_months,E12,F12) -> 315905.42 | H12: =G12-D12 -> -4382.34 | I12: =IF(D12=0,"",H12/D12) -> -0.013682509 | J12: =J11+H12 -> -39135.73
A13: Engineering | B13: Sep | C13: 9 | D13: 327264.98 | F13: =IF(C13<=fact_months,"",ROUND(D13*(1+Equalisation!$G$8/100)+IF(C13>=equalisation_month,Equalisation!$F$8,0),2)) -> 330717.45 | G13: =IF(C13<=fact_months,E13,F13) -> 330717.45 | H13: =G13-D13 -> 3452.47 | I13: =IF(D13=0,"",H13/D13) -> 0.010549464 | J13: =J12+H13 -> -35683.26
A14: Engineering | B14: Oct | C14: 10 | D14: 334242.21 | F14: =IF(C14<=fact_months,"",ROUND(D14*(1+Equalisation!$G$8/100)+IF(C14>=equalisation_month,Equalisation!$F$8,0),2)) -> 337594.13 | G14: =IF(C14<=fact_months,E14,F14) -> 337594.13 | H14: =G14-D14 -> 3351.92 | I14: =IF(D14=0,"",H14/D14) -> 0.010028416 | J14: =J13+H14 -> -32331.34
A15: Engineering | B15: Nov | C15: 11 | D15: 336900.2 | F15: =IF(C15<=fact_months,"",ROUND(D15*(1+Equalisation!$G$8/100)+IF(C15>=equalisation_month,Equalisation!$F$8,0),2)) -> 340213.82 | G15: =IF(C15<=fact_months,E15,F15) -> 340213.82 | H15: =G15-D15 -> 3313.62 | I15: =IF(D15=0,"",H15/D15) -> 0.009835613 | J15: =J14+H15 -> -29017.72
A16: Engineering | B16: Dec | C16: 12 | D16: 337232.45 | F16: =IF(C16<=fact_months,"",ROUND(D16*(1+Equalisation!$G$8/100)+IF(C16>=equalisation_month,Equalisation!$F$8,0),2)) -> 340541.29 | G16: =IF(C16<=fact_months,E16,F16) -> 340541.29 | H16: =G16-D16 -> 3308.84 | I16: =IF(D16=0,"",H16/D16) -> 0.0098117485 | J16: =J15+H16 -> -25708.88
A17: Sales | B17: Jan | C17: 1 | D17: 242838.79 | E17: 265129.16 | F17: =IF(C17<=fact_months,"",ROUND(D17*(1+Equalisation!$G$9/100)+IF(C17>=equalisation_month,Equalisation!$F$9,0),2)) | G17: =IF(C17<=fact_months,E17,F17) -> 265129.16 | H17: =G17-D17 -> 22290.37 | I17: =IF(D17=0,"",H17/D17) -> 0.091790813 | J17: =H17 -> 22290.37
A18: Sales | B18: Feb | C18: 2 | D18: 242136.94 | E18: 264282.53 | F18: =IF(C18<=fact_months,"",ROUND(D18*(1+Equalisation!$G$9/100)+IF(C18>=equalisation_month,Equalisation!$F$9,0),2)) | G18: =IF(C18<=fact_months,E18,F18) -> 264282.53 | H18: =G18-D18 -> 22145.59 | I18: =IF(D18=0,"",H18/D18) -> 0.091458949 | J18: =J17+H18 -> 44435.96
A19: Sales | B19: Mar | C19: 3 | D19: 239095.61 | E19: 261059.03 | F19: =IF(C19<=fact_months,"",ROUND(D19*(1+Equalisation!$G$9/100)+IF(C19>=equalisation_month,Equalisation!$F$9,0),2)) | G19: =IF(C19<=fact_months,E19,F19) -> 261059.03 | H19: =G19-D19 -> 21963.42 | I19: =IF(D19=0,"",H19/D19) -> 0.091860407 | J19: =J18+H19 -> 66399.38
A20: Sales | B20: Apr | C20: 4 | D20: 235118.48 | E20: 256678.84 | F20: =IF(C20<=fact_months,"",ROUND(D20*(1+Equalisation!$G$9/100)+IF(C20>=equalisation_month,Equalisation!$F$9,0),2)) | G20: =IF(C20<=fact_months,E20,F20) -> 256678.84 | H20: =G20-D20 -> 21560.36 | I20: =IF(D20=0,"",H20/D20) -> 0.09169998 | J20: =J19+H20 -> 87959.74
A21: Sales | B21: May | C21: 5 | D21: 230673.45 | E21: 251975.28 | F21: =IF(C21<=fact_months,"",ROUND(D21*(1+Equalisation!$G$9/100)+IF(C21>=equalisation_month,Equalisation!$F$9,0),2)) | G21: =IF(C21<=fact_months,E21,F21) -> 251975.28 | H21: =G21-D21 -> 21301.83 | I21: =IF(D21=0,"",H21/D21) -> 0.092346258 | J21: =J20+H21 -> 109261.57
A22: Sales | B22: Jun | C22: 6 | D22: 226462.37 | E22: 247614.74 | F22: =IF(C22<=fact_months,"",ROUND(D22*(1+Equalisation!$G$9/100)+IF(C22>=equalisation_month,Equalisation!$F$9,0),2)) | G22: =IF(C22<=fact_months,E22,F22) -> 247614.74 | H22: =G22-D22 -> 21152.37 | I22: =IF(D22=0,"",H22/D22) -> 0.093403465 | J22: =J21+H22 -> 130413.94
A23: Sales | B23: Jul | C23: 7 | D23: 225058.68 | E23: 246001.24 | F23: =IF(C23<=fact_months,"",ROUND(D23*(1+Equalisation!$G$9/100)+IF(C23>=equalisation_month,Equalisation!$F$9,0),2)) | G23: =IF(C23<=fact_months,E23,F23) -> 246001.24 | H23: =G23-D23 -> 20942.56 | I23: =IF(D23=0,"",H23/D23) -> 0.093053776 | J23: =J22+H23 -> 151356.5
A24: Sales | B24: Aug | C24: 8 | D24: 225526.58 | E24: 246679.43 | F24: =IF(C24<=fact_months,"",ROUND(D24*(1+Equalisation!$G$9/100)+IF(C24>=equalisation_month,Equalisation!$F$9,0),2)) | G24: =IF(C24<=fact_months,E24,F24) -> 246679.43 | H24: =G24-D24 -> 21152.85 | I24: =IF(D24=0,"",H24/D24) -> 0.093793157 | J24: =J23+H24 -> 172509.35
A25: Sales | B25: Sep | C25: 9 | D25: 230439.5 | F25: =IF(C25<=fact_months,"",ROUND(D25*(1+Equalisation!$G$9/100)+IF(C25>=equalisation_month,Equalisation!$F$9,0),2)) -> 262584.74 | G25: =IF(C25<=fact_months,E25,F25) -> 262584.74 | H25: =G25-D25 -> 32145.24 | I25: =IF(D25=0,"",H25/D25) -> 0.13949536 | J25: =J24+H25 -> 204654.59
A26: Sales | B26: Oct | C26: 10 | D26: 235352.43 | F26: =IF(C26<=fact_months,"",ROUND(D26*(1+Equalisation!$G$9/100)+IF(C26>=equalisation_month,Equalisation!$F$9,0),2)) -> 267952.29 | G26: =IF(C26<=fact_months,E26,F26) -> 267952.29 | H26: =G26-D26 -> 32599.86 | I26: =IF(D26=0,"",H26/D26) -> 0.13851508 | J26: =J25+H26 -> 237254.45
A27: Sales | B27: Nov | C27: 11 | D27: 237224.02 | F27: =IF(C27<=fact_months,"",ROUND(D27*(1+Equalisation!$G$9/100)+IF(C27>=equalisation_month,Equalisation!$F$9,0),2)) -> 269997.07 | G27: =IF(C27<=fact_months,E27,F27) -> 269997.07 | H27: =G27-D27 -> 32773.05 | I27: =IF(D27=0,"",H27/D27) -> 0.13815233 | J27: =J26+H27 -> 270027.5
A28: Sales | B28: Dec | C28: 12 | D28: 237457.97 | F28: =IF(C28<=fact_months,"",ROUND(D28*(1+Equalisation!$G$9/100)+IF(C28>=equalisation_month,Equalisation!$F$9,0),2)) -> 270252.66 | G28: =IF(C28<=fact_months,E28,F28) -> 270252.66 | H28: =G28-D28 -> 32794.69 | I28: =IF(D28=0,"",H28/D28) -> 0.13810735 | J28: =J27+H28 -> 302822.19
A29: Operations | B29: Jan | C29: 1 | D29: 228283.47 | E29: 231390.85 | F29: =IF(C29<=fact_months,"",ROUND(D29*(1+Equalisation!$G$10/100)+IF(C29>=equalisation_month,Equalisation!$F$10,0),2)) | G29: =IF(C29<=fact_months,E29,F29) -> 231390.85 | H29: =G29-D29 -> 3107.38 | I29: =IF(D29=0,"",H29/D29) -> 0.013611936 | J29: =H29 -> 3107.38
A30: Operations | B30: Feb | C30: 2 | D30: 227623.69 | E30: 230690.86 | F30: =IF(C30<=fact_months,"",ROUND(D30*(1+Equalisation!$G$10/100)+IF(C30>=equalisation_month,Equalisation!$F$10,0),2)) | G30: =IF(C30<=fact_months,E30,F30) -> 230690.86 | H30: =G30-D30 -> 3067.17 | I30: =IF(D30=0,"",H30/D30) -> 0.01347474 | J30: =J29+H30 -> 6174.55
A31: Operations | B31: Mar | C31: 3 | D31: 224764.65 | E31: 227525.39 | F31: =IF(C31<=fact_months,"",ROUND(D31*(1+Equalisation!$G$10/100)+IF(C31>=equalisation_month,Equalisation!$F$10,0),2)) | G31: =IF(C31<=fact_months,E31,F31) -> 227525.39 | H31: =G31-D31 -> 2760.74 | I31: =IF(D31=0,"",H31/D31) -> 0.012282803 | J31: =J30+H31 -> 8935.29
A32: Operations | B32: Apr | C32: 4 | D32: 221025.9 | E32: 224049.75 | F32: =IF(C32<=fact_months,"",ROUND(D32*(1+Equalisation!$G$10/100)+IF(C32>=equalisation_month,Equalisation!$F$10,0),2)) | G32: =IF(C32<=fact_months,E32,F32) -> 224049.75 | H32: =G32-D32 -> 3023.85 | I32: =IF(D32=0,"",H32/D32) -> 0.013680976 | J32: =J31+H32 -> 11959.14
A33: Operations | B33: May | C33: 5 | D33: 216847.3 | E33: 219787.72 | F33: =IF(C33<=fact_months,"",ROUND(D33*(1+Equalisation!$G$10/100)+IF(C33>=equalisation_month,Equalisation!$F$10,0),2)) | G33: =IF(C33<=fact_months,E33,F33) -> 219787.72 | H33: =G33-D33 -> 2940.42 | I33: =IF(D33=0,"",H33/D33) -> 0.013559864 | J33: =J32+H33 -> 14899.56
A34: Operations | B34: Jun | C34: 6 | D34: 212888.63 | E34: 216019.66 | F34: =IF(C34<=fact_months,"",ROUND(D34*(1+Equalisation!$G$10/100)+IF(C34>=equalisation_month,Equalisation!$F$10,0),2)) | G34: =IF(C34<=fact_months,E34,F34) -> 216019.66 | H34: =G34-D34 -> 3131.03 | I34: =IF(D34=0,"",H34/D34) -> 0.014707361 | J34: =J33+H34 -> 18030.59
A35: Operations | B35: Jul | C35: 7 | D35: 211569.07 | E35: 214065.27 | F35: =IF(C35<=fact_months,"",ROUND(D35*(1+Equalisation!$G$10/100)+IF(C35>=equalisation_month,Equalisation!$F$10,0),2)) | G35: =IF(C35<=fact_months,E35,F35) -> 214065.27 | H35: =G35-D35 -> 2496.2 | I35: =IF(D35=0,"",H35/D35) -> 0.011798511 | J35: =J34+H35 -> 20526.79
A36: Operations | B36: Aug | C36: 8 | D36: 212008.92 | E36: 214745.39 | F36: =IF(C36<=fact_months,"",ROUND(D36*(1+Equalisation!$G$10/100)+IF(C36>=equalisation_month,Equalisation!$F$10,0),2)) | G36: =IF(C36<=fact_months,E36,F36) -> 214745.39 | H36: =G36-D36 -> 2736.47 | I36: =IF(D36=0,"",H36/D36) -> 0.012907334 | J36: =J35+H36 -> 23263.26
A37: Operations | B37: Sep | C37: 9 | D37: 216627.38 | F37: =IF(C37<=fact_months,"",ROUND(D37*(1+Equalisation!$G$10/100)+IF(C37>=equalisation_month,Equalisation!$F$10,0),2)) -> 221281.25 | G37: =IF(C37<=fact_months,E37,F37) -> 221281.25 | H37: =G37-D37 -> 4653.87 | I37: =IF(D37=0,"",H37/D37) -> 0.021483295 | J37: =J36+H37 -> 27917.13
A38: Operations | B38: Oct | C38: 10 | D38: 221245.83 | F38: =IF(C38<=fact_months,"",ROUND(D38*(1+Equalisation!$G$10/100)+IF(C38>=equalisation_month,Equalisation!$F$10,0),2)) -> 225961.01 | G38: =IF(C38<=fact_months,E38,F38) -> 225961.01 | H38: =G38-D38 -> 4715.18 | I38: =IF(D38=0,"",H38/D38) -> 0.02131195 | J38: =J37+H38 -> 32632.31
A39: Operations | B39: Nov | C39: 11 | D39: 223005.24 | F39: =IF(C39<=fact_months,"",ROUND(D39*(1+Equalisation!$G$10/100)+IF(C39>=equalisation_month,Equalisation!$F$10,0),2)) -> 227743.78 | G39: =IF(C39<=fact_months,E39,F39) -> 227743.78 | H39: =G39-D39 -> 4738.54 | I39: =IF(D39=0,"",H39/D39) -> 0.021248559 | J39: =J38+H39 -> 37370.85
A40: Operations | B40: Dec | C40: 12 | D40: 223225.16 | F40: =IF(C40<=fact_months,"",ROUND(D40*(1+Equalisation!$G$10/100)+IF(C40>=equalisation_month,Equalisation!$F$10,0),2)) -> 227966.61 | G40: =IF(C40<=fact_months,E40,F40) -> 227966.61 | H40: =G40-D40 -> 4741.45 | I40: =IF(D40=0,"",H40/D40) -> 0.021240661 | J40: =J39+H40 -> 42112.3
A41: Manufacturing | B41: Jan | C41: 1 | D41: 218086.63 | E41: 223337.15 | F41: =IF(C41<=fact_months,"",ROUND(D41*(1+Equalisation!$G$11/100)+IF(C41>=equalisation_month,Equalisation!$F$11,0),2)) | G41: =IF(C41<=fact_months,E41,F41) -> 223337.15 | H41: =G41-D41 -> 5250.52 | I41: =IF(D41=0,"",H41/D41) -> 0.024075387 | J41: =H41 -> 5250.52
...

Sheet Monthly
A1: Company total by month
A2: Two different quantities, and the dashboard must keep them apart: the monthly deviation says how far this month ran from plan, while the cumulative one carries every month before it. On this dataset both are positive from January, and the monthly figure roughly doubles once equalisation starts.
A5: Month | B5: # | C5: Plan, EUR | D5: Expected, EUR | E5: Deviation, EUR | F5: Deviation, % | G5: Cumulative, EUR
A6: Jan | B6: 1 | C6: =SUMIF(Data!$C$5:$C$88,$B6,Data!$D$5:$D$88) -> 1431549.2 | D6: =SUMIF(Data!$C$5:$C$88,$B6,Data!$G$5:$G$88) -> 1466464.8 | E6: =D6-C6 -> 34915.59 | F6: =E6/C6 -> 0.024390074 | G6: =E6 -> 34915.59
A7: Feb | B7: 2 | C7: =SUMIF(Data!$C$5:$C$88,$B7,Data!$D$5:$D$88) -> 1427411.8 | D7: =SUMIF(Data!$C$5:$C$88,$B7,Data!$G$5:$G$88) -> 1462002.4 | E7: =D7-C7 -> 34590.65 | F7: =E7/C7 -> 0.024233127 | G7: =G6+E7 -> 69506.24
A8: Mar | B8: 3 | C8: =SUMIF(Data!$C$5:$C$88,$B8,Data!$D$5:$D$88) -> 1409482.9 | D8: =SUMIF(Data!$C$5:$C$88,$B8,Data!$G$5:$G$88) -> 1443777.9 | E8: =D8-C8 -> 34294.94 | F8: =E8/C8 -> 0.024331576 | G8: =G7+E8 -> 103801.18
A9: Apr | B9: 4 | C9: =SUMIF(Data!$C$5:$C$88,$B9,Data!$D$5:$D$88) -> 1386037.5 | D9: =SUMIF(Data!$C$5:$C$88,$B9,Data!$G$5:$G$88) -> 1420273.4 | E9: =D9-C9 -> 34235.9 | F9: =E9/C9 -> 0.024700558 | G9: =G8+E9 -> 138037.08
A10: May | B10: 5 | C10: =SUMIF(Data!$C$5:$C$88,$B10,Data!$D$5:$D$88) -> 1359833.8 | D10: =SUMIF(Data!$C$5:$C$88,$B10,Data!$G$5:$G$88) -> 1393836.3 | E10: =D10-C10 -> 34002.55 | F10: =E10/C10 -> 0.025004931 | G10: =G9+E10 -> 172039.63
A11: Jun | B11: 6 | C11: =SUMIF(Data!$C$5:$C$88,$B11,Data!$D$5:$D$88) -> 1335009.2 | D11: =SUMIF(Data!$C$5:$C$88,$B11,Data!$G$5:$G$88) -> 1368196.3 | E11: =D11-C11 -> 33187.03 | F11: =E11/C11 -> 0.024859026 | G11: =G10+E11 -> 205226.66
A12: Jul | B12: 7 | C12: =SUMIF(Data!$C$5:$C$88,$B12,Data!$D$5:$D$88) -> 1326734.4 | D12: =SUMIF(Data!$C$5:$C$88,$B12,Data!$G$5:$G$88) -> 1358760.2 | E12: =D12-C12 -> 32025.86 | F12: =E12/C12 -> 0.024138863 | G12: =G11+E12 -> 237252.52
A13: Aug | B13: 8 | C13: =SUMIF(Data!$C$5:$C$88,$B13,Data!$D$5:$D$88) -> 1329492.7 | D13: =SUMIF(Data!$C$5:$C$88,$B13,Data!$G$5:$G$88) -> 1362405.7 | E13: =D13-C13 -> 32913.01 | F13: =E13/C13 -> 0.024756067 | G13: =G12+E13 -> 270165.53
A14: Sep | B14: 9 | C14: =SUMIF(Data!$C$5:$C$88,$B14,Data!$D$5:$D$88) -> 1358454.7 | D14: =SUMIF(Data!$C$5:$C$88,$B14,Data!$G$5:$G$88) -> 1424841.4 | E14: =D14-C14 -> 66386.79 | F14: =E14/C14 -> 0.048869345 | G14: =G13+E14 -> 336552.32
A15: Oct | B15: 10 | C15: =SUMIF(Data!$C$5:$C$88,$B15,Data!$D$5:$D$88) -> 1387416.6 | D15: =SUMIF(Data!$C$5:$C$88,$B15,Data!$G$5:$G$88) -> 1454514.3 | E15: =D15-C15 -> 67097.66 | F15: =E15/C15 -> 0.048361579 | G15: =G14+E15 -> 403649.98
A16: Nov | B16: 11 | C16: =SUMIF(Data!$C$5:$C$88,$B16,Data!$D$5:$D$88) -> 1398449.8 | D16: =SUMIF(Data!$C$5:$C$88,$B16,Data!$G$5:$G$88) -> 1465818.3 | E16: =D16-C16 -> 67368.48 | F16: =E16/C16 -> 0.048173685 | G16: =G15+E16 -> 471018.46
A17: Dec | B17: 12 | C17: =SUMIF(Data!$C$5:$C$88,$B17,Data!$D$5:$D$88) -> 1399828.9 | D17: =SUMIF(Data!$C$5:$C$88,$B17,Data!$G$5:$G$88) -> 1467231.2 | E17: =D17-C17 -> 67402.32 | F17: =E17/C17 -> 0.048150399 | G17: =G16+E17 -> 538420.78
A18: YEAR | C18: =SUM(C6:C17) -> 16549701 | D18: =SUM(D6:D17) -> 17088122 | E18: =SUM(E6:E17) -> 538420.78 | F18: =E18/C18 -> 0.032533565

Sheet Departments
A1: By department: eight months of actuals against the year
A2: Sign of the deviation is stable within a department: it either underspends all year or overspends all year. On this dataset six of seven overspend; Engineering is the one that does not.
A4: Department | B4: Plan 8M, EUR | C4: Actual 8M, EUR | D4: Deviation 8M, EUR | E4: Deviation 8M, % | F4: Equalisation, EUR | G4: Year plan, EUR | H4: Year expected, EUR | I4: Year deviation, EUR | J4: Year, %
A5: Engineering | B5: =SUMIF(Data!$C$5:$C$16,"<="&fact_months,Data!$D$5:$D$16) -> 2651344.8 | C5: =SUMIF(Data!$C$5:$C$16,"<="&fact_months,Data!$E$5:$E$16) -> 2612209 | D5: =C5-B5 -> -39135.73 | E5: =D5/B5 -> -0.01476071 | F5: =SUMIFS(Data!$F$5:$F$16,Data!$C$5:$C$16,">="&equalisation_month)-SUMIFS(Data!$D$5:$D$16,Data!$C$5:$C$16,">="&equalisation_month) -> 13426.85 | G5: =SUM(Data!$D$5:$D$16) -> 3986984.6 | H5: =SUM(Data!$G$5:$G$16) -> 3961275.7 | I5: =H5-G5 -> -25708.88 | J5: =I5/G5 -> -0.0064482015
A6: Sales | B6: =SUMIF(Data!$C$17:$C$28,"<="&fact_months,Data!$D$17:$D$28) -> 1866910.9 | C6: =SUMIF(Data!$C$17:$C$28,"<="&fact_months,Data!$E$17:$E$28) -> 2039420.2 | D6: =C6-B6 -> 172509.35 | E6: =D6/B6 -> 0.092403633 | F6: =SUMIFS(Data!$F$17:$F$28,Data!$C$17:$C$28,">="&equalisation_month)-SUMIFS(Data!$D$17:$D$28,Data!$C$17:$C$28,">="&equalisation_month) -> 130312.84 | G6: =SUM(Data!$D$17:$D$28) -> 2807384.8 | H6: =SUM(Data!$G$17:$G$28) -> 3110207 | I6: =H6-G6 -> 302822.19 | J6: =I6/G6 -> 0.10786629
A7: Operations | B7: =SUMIF(Data!$C$29:$C$40,"<="&fact_months,Data!$D$29:$D$40) -> 1755011.6 | C7: =SUMIF(Data!$C$29:$C$40,"<="&fact_months,Data!$E$29:$E$40) -> 1778274.9 | D7: =C7-B7 -> 23263.26 | E7: =D7/B7 -> 0.013255331 | F7: =SUMIFS(Data!$F$29:$F$40,Data!$C$29:$C$40,">="&equalisation_month)-SUMIFS(Data!$D$29:$D$40,Data!$C$29:$C$40,">="&equalisation_month) -> 18849.04 | G7: =SUM(Data!$D$29:$D$40) -> 2639115.2 | H7: =SUM(Data!$G$29:$G$40) -> 2681227.5 | I7: =H7-G7 -> 42112.3 | J7: =I7/G7 -> 0.015956977
A8: Manufacturing | B8: =SUMIF(Data!$C$41:$C$52,"<="&fact_months,Data!$D$41:$D$52) -> 1676619.8 | C8: =SUMIF(Data!$C$41:$C$52,"<="&fact_months,Data!$E$41:$E$52) -> 1716355.4 | D8: =C8-B8 -> 39735.64 | E8: =D8/B8 -> 0.023699852 | F8: =SUMIFS(Data!$F$41:$F$52,Data!$C$41:$C$52,">="&equalisation_month)-SUMIFS(Data!$D$41:$D$52,Data!$C$41:$C$52,">="&equalisation_month) -> 48817.21 | G8: =SUM(Data!$D$41:$D$52) -> 2521232.8 | H8: =SUM(Data!$G$41:$G$52) -> 2609785.6 | I8: =H8-G8 -> 88552.85 | J8: =I8/G8 -> 0.035122838
A9: Marketing | B9: =SUMIF(Data!$C$53:$C$64,"<="&fact_months,Data!$D$53:$D$64) -> 1546798.2 | C9: =SUMIF(Data!$C$53:$C$64,"<="&fact_months,Data!$E$53:$E$64) -> 1585034.4 | D9: =C9-B9 -> 38236.13 | E9: =D9/B9 -> 0.024719533 | F9: =SUMIFS(Data!$F$53:$F$64,Data!$C$53:$C$64,">="&equalisation_month)-SUMIFS(Data!$D$53:$D$64,Data!$C$53:$C$64,">="&equalisation_month) -> 18958.21 | G9: =SUM(Data!$D$53:$D$64) -> 2326012.4 | H9: =SUM(Data!$G$53:$G$64) -> 2383206.7 | I9: =H9-G9 -> 57194.34 | J9: =I9/G9 -> 0.024589009
A10: Customer Support | B10: =SUMIF(Data!$C$65:$C$76,"<="&fact_months,Data!$D$65:$D$76) -> 938893.38 | C10: =SUMIF(Data!$C$65:$C$76,"<="&fact_months,Data!$E$65:$E$76) -> 959203.63 | D10: =C10-B10 -> 20310.25 | E10: =D10/B10 -> 0.021632115 | F10: =SUMIFS(Data!$F$65:$F$76,Data!$C$65:$C$76,">="&equalisation_month)-SUMIFS(Data!$D$65:$D$76,Data!$C$65:$C$76,">="&equalisation_month) -> 24108.85 | G10: =SUM(Data!$D$65:$D$76) -> 1411869.8 | H10: =SUM(Data!$G$65:$G$76) -> 1456288.9 | I10: =H10-G10 -> 44419.1 | J10: =I10/G10 -> 0.031461188
A11: Legal | B11: =SUMIF(Data!$C$77:$C$88,"<="&fact_months,Data!$D$77:$D$88) -> 569972.74 | C11: =SUMIF(Data!$C$77:$C$88,"<="&fact_months,Data!$E$77:$E$88) -> 585219.37 | D11: =C11-B11 -> 15246.63 | E11: =D11/B11 -> 0.026749753 | F11: =SUMIFS(Data!$F$77:$F$88,Data!$C$77:$C$88,">="&equalisation_month)-SUMIFS(Data!$D$77:$D$88,Data!$C$77:$C$88,">="&equalisation_month) -> 13782.25 | G11: =SUM(Data!$D$77:$D$88) -> 857101.87 | H11: =SUM(Data!$G$77:$G$88) -> 886130.75 | I11: =H11-G11 -> 29028.88 | J11: =I11/G11 -> 0.033868646
A12: TOTAL | B12: =SUM(B5:B11) -> 11005551 | C12: =SUM(C5:C11) -> 11275717 | D12: =SUM(D5:D11) -> 270165.53 | E12: =D12/B12 -> 0.024548114 | F12: =SUM(F5:F11) -> 268255.25 | G12: =SUM(G5:G11) -> 16549701 | H12: =SUM(H5:H11) -> 17088122 | I12: =SUM(I5:I11) -> 538420.78 | J12: =I12/G12 -> 0.032533565

Sheet Summary
A1: Summary | D1: cells_for_check
A2: Every figure here is a formula. Change an actual on the Data sheet and watch this recalculate. | D2: plan8 | E2: B5
D3: fact8 | E3: B6
A4: Eight months of actuals | D4: yplan | E4: B15
A5: Plan, Jan-Aug | B5: =SUMIF(Monthly!$B$6:$B$17,"<="&fact_months,Monthly!$C$6:$C$17) -> 11005551 | D5: yexp | E5: B16
A6: Actual, Jan-Aug | B6: =SUMIF(Monthly!$B$6:$B$17,"<="&fact_months,Monthly!$D$6:$D$17) -> 11275717 | D6: ydelta | E6: B17
A7: Accumulated deviation | B7: =B6-B5 -> 270165.53 | D7: cross | E7: B20
A8: As % of plan | B8: =B7/B5 -> 0.024548114
A10: Cost of closing the gap
A11: Annual cost of equalisation | B11: =Equalisation!$E$15 -> 396521.57
A12: Charged this year (from month 9) | B12: =SUMIFS(Data!$F$5:$F$88,Data!$C$5:$C$88,">="&equalisation_month)-SUMIFS(Data!$D$5:$D$88,Data!$C$5:$C$88,">="&equalisation_month) -> 268255.25
A14: Full year
A15: Plan | B15: =Monthly!$C$18 -> 16549701
A16: Expected (actual + forecast) | B16: =Monthly!$D$18 -> 17088122
A17: Deviation | B17: =B16-B15 -> 538420.78
A18: As % of plan | B18: =B17/B15 -> 0.032533565
A20: First month the cumulative is above plan | B20: =INDEX(Monthly!$A$6:$A$17,MATCH(TRUE,INDEX(Monthly!$G$6:$G$17>0,0),0)) -> Jan
A23: Deviation is expected minus plan throughout. A positive figure means the company spent more than planned, a negative one less. On this dataset the deviation is positive from January and the cumulative never returns to plan.

Sheet Legend
A1: Legend and method
A3: Colours
A4: Yellow | B4: Source data. Comes from the CSV, never calculated.
A5: Blue | B5: Calculated by formula. These cells recalculate themselves.
A6: Green | B6: A setting on the Settings sheet. These are meant to be changed.
A8: Order of calculation
A9: 1. Plan | B9: Annual payroll including employer contributions, spread over twelve months with holiday-reserve seasonality: higher at the start and end of the year, lower over the summer, when headcount is thin and accrued leave is taken. The seasonal coefficients sum to twelve, so seasonality moves money inside the year without changing the annual total.
A10: 2. Actual | B10: Months 1..fact_months. Each department's deviation keeps a stable sign: it either underspends all year or overspends all year. One department is deliberately well outside the others' range: budgets rarely break evenly, they break in one place.
A11: 3. Forecast | B11: For the remaining months, the department's own deviation carries forward and the monthly equalisation uplift is added on top, from the equalisation month onwards. The uplift is the annual cost of closing the pay gap divided by twelve. This is why deviation runs higher in the last four months than in the first eight: the pay rise lands on top of a gap that was already there.
A12: 4. Deviation | B12: Expected minus plan. Positive is an overspend. Shown both per month and as a running total from January.
A13: 5. Year | B13: Plan against actual plus forecast. The accumulated deviation is set against the cost of equalisation charged this year.
A15: Two quantities not to confuse
A16: Monthly deviation | B16: How far this one month ran from plan. It answers: is this month worse than the last. On this dataset it roughly doubles in the equalisation month.
A17: Cumulative deviation | B17: The same figure carried from January, so it answers a different question: how much of the year's budget has gone. A month can improve while the cumulative still grows. Both are correct; do not read one for the other.
A19: What this model does not do
A20: No explanation of variances | B20: It shows where and by how much, not why. Causes belong in the conversation, not on the screen.
A21: Employer contributions | B21: A raise to base pay brings employer contributions with it, and those are part of the budget line. The rates here are Spain 2026: 31.5% on annual pay up to a ceiling of 61,214 EUR, and 1.15% on anything above it. The scale is regressive, so a raise to someone already above the ceiling attracts almost no contributions while the same raise below it attracts the full rate. That is why the effective rate on the Equalisation sheet differs so much between departments. Rates and ceiling are specific to one country and one year: in another jurisdiction the numbers change, the structure does not.
A22: Synthetic data | B22: Generated from a seeded PRNG, not from any real organisation. The workbook illustrates a budgeting approach and is not legal or actuarial advice.
