Workbook
Name AboveCeilingTier1: Inputs!$B$15
Name AboveCeilingTier2: Inputs!$B$16
Name AboveCeilingTier3: Inputs!$B$17
Name Ceiling: Inputs!$B$14
Name ClipAtMax: Inputs!$B$11
Name CompanyTarget: Inputs!$B$12
Name EffDate: Inputs!$B$4
Name EffMonth: Inputs!$B$5
Name InYearFactor: Inputs!$B$6
Name MaxIncrease: Inputs!$B$10
Name MinMonthsChange: Inputs!$B$9
Name MinMonthsHire: Inputs!$B$8
Name PoolPct: Inputs!$B$7
Name RateBelow: Inputs!$B$13

Sheet Summary
A1: Summary: what the review costs
B3: Value
A4: Headcount | B4: =COUNT(Calc!$I:$I) -> 212
A5: Eligible for merit | B5: =SUM(Calc!$AH:$AH) -> 209
A7: PAYROLL COST: full year, incl. employer contributions
A8: Current payroll cost | B8: =SUM(Calc!$BA:$BA)+SUM(Calc!$BB:$BB) -> 16557322
A9: of which total cash (base + bonus) | B9: =SUM(Calc!$BA:$BA) -> 12970151
A10: of which employer contributions | B10: =SUM(Calc!$BB:$BB) -> 3587171
A11: Payroll cost after pay equity | B11: =SUM(Calc!$BC:$BC)+SUM(Calc!$BD:$BD) -> 16890080
A12: Payroll cost after merit review | B12: =SUM(Calc!$BE:$BE)+SUM(Calc!$BF:$BF) -> 17676509
A13: Change: pay equity | B13: =B11-B8 -> 332757.14
A14: Change: merit review | B14: =B12-B11 -> 786429.76
A15: Change: total | B15: =B12-B8 -> 1119186.9
A16: Change: total, % of current payroll cost | B16: =IF(B8>0,B15/B8,0) -> 0.067594679
A18: THIS YEAR: from the effective month
A19: Change this year: pay equity | B19: =B13*InYearFactor -> 249567.85
A20: Change this year: merit review | B20: =B14*InYearFactor -> 589822.32
A21: Change this year: total | B21: =B19+B20 -> 839390.17
A22: Change this year, % of current payroll cost | B22: =IF(B8>0,B21/B8,0) -> 0.050696009
A24: PAY EQUITY ADJUSTMENT (Calc step 2), breakdown
A25: Base adjustment | B25: =SUM(Calc!$BG:$BG) -> 257991.67
A26: Bonus effect | B26: =SUM(Calc!$BH:$BH) -> 27282.115
A27: Employer contributions | B27: =SUM(Calc!$BI:$BI) -> 47483.359
A28: Total, full year | B28: =B25+B26+B27 -> 332757.14
A29: Total, this year | B29: =B28*InYearFactor -> 249567.85
A31: MERIT INCREASE from the aligned base (Calc step 5), breakdown
A32: Merit increase (base) | B32: =SUM(Calc!$BJ:$BJ) -> 637569.71
A33: Bonus effect | B33: =SUM(Calc!$BK:$BK) -> 90440.597
A34: Employer contributions | B34: =SUM(Calc!$BL:$BL) -> 58419.452
A35: Total, full year | B35: =B32+B33+B34 -> 786429.76
A36: Total, this year | B36: =B35*InYearFactor -> 589822.32
A38: MERIT REVIEW VS TARGET BUDGET, incl. bonus and employer contributions
A39: Eligible base payroll | B39: =SUM(Calc!$BM:$BM) -> 11819694
A40: Target merit increase, % of eligible base payroll (change on Inputs) | B40: =PoolPct -> 0.04
A41: Merit increase as calculated, % of eligible base payroll | B41: =IF(B39>0,B32/B39,0) -> 0.053941305
A42: Variance vs target, pp (+ over, − under) | B42: =(B41-B40)*100 -> 1.3941305
A43: Target budget, full year | B43: =B44+B45+B46 -> 586858.83
A44: of which base | B44: =SUM(Calc!$BO:$BO) -> 472787.75
A45: of which bonus | B45: =SUM(Calc!$BP:$BP) -> 51551.713
A46: of which employer contributions | B46: =SUM(Calc!$BS:$BS) -> 62519.368
...

Sheet Inputs
A1: Inputs: change the yellow cells
A3: Setting | B3: Value | C3: Note
A4: Effective from (pick a month) | B4: 46478 | C4: Increases take effect on the 1st of this month. Eligibility is counted up to it. Pick from the list.
A5: Effective month | B5: =MONTH(EffDate) -> 4 | C5: Month number of the effective date.
A6: In-year proration factor | B6: =(13-EffMonth)/12 -> 0.75 | C6: Months from the effective month to December inclusive, ÷ 12; the increase is assumed to start on the 1st of that month.
A7: Target merit increase, % of eligible base payroll | B7: 0.04 | C7: The planned average increase, as % of eligible staff's annual base after the pay equity step, FTE-weighted. The target budget on Summary is this % given to every eligible person, with bonus and employer contributions.
A8: Minimum tenure, months | B8: 6 | C8: Hired fewer months before the effective date than this: not in the review. Hired after the effective date: never in it.
A9: No individual pay change in the last, months | B9: 3 | C9: Individual pay change fewer months before the effective date than this: not in the review.
A10: Increase cap per person, % of aligned base | B10: 0.3 | C10: A safety limit. The increase is each person's gap to target, or the rating minimum if higher; the cap only cuts it if it is larger. 'No cap' (or an empty cell, or 0%) = no limit.
A11: Clip increases at range maximum | B11: Yes | C11: Yes: a merit increase never takes base pay above the range maximum. The pay equity adjustment is not clipped.
A12: Pay policy position, % of range midpoint | B12: 1 | C12: Leave at 100% if your range midpoints already reflect your pay policy.
A13: Employer contribution rate up to the ceiling | B13: 0.3215 | C13: Default: Spain 2026, 30.65% (permanent contracts; fixed-term 31.85%) + AT/EP occupational accident and disease premium, office-work rate 1.50% (RDL 3/2026, Cuadro II a) = 32.15%. Use your activity's AT/EP rate. These are 2026 rates. Rates for 2027 are already set and slightly higher (MEI employer share 0.83%, higher solidarity rates); 2026 rates are kept, so the contribution cost of a 2027 review is slightly understated.
A14: Annual contribution ceiling | B14: 61214.4 | C14: Default: Spain 2026, €5,101.20 a month × 12 (Orden PJC/297/2026). 2027 not yet published: 2026 assumed.
A15: Rate above the ceiling, tier 1: up to 10% over the ceiling | B15: 0.0096 | C15: Employer rate on the part of pay above the ceiling. Set 0% in all three tiers if your country charges nothing above it. Default: Spain 2026 (cuota de solidaridad), employer share, 0.96%.
A16: Rate above the ceiling, tier 2: 10% to 50% over the ceiling | B16: 0.0104 | C16: Default: Spain 2026, employer share, 1.04%.
A17: Rate above the ceiling, tier 3: more than 50% over the ceiling | B17: 0.0122 | C17: Default: Spain 2026, employer share, 1.22%.
A19: Targets by performance rating (illustrative assumption: set your own)
A20: Rating | B20: Label | C20: Target compa-ratio | D20: Minimum increase, % of aligned base
A21: 1 | B21: Unsatisfactory | C21: 0 | D21: 0
A22: 2 | B22: Partially meets | C22: 0.95 | D22: 0
A23: 3 | B23: Meets | C23: 1 | D23: 0
A24: 4 | B24: Exceeds | C24: 1.05 | D24: 0.01
A25: 5 | B25: Outstanding | C25: 1.1 | D25: 0.02
A26: Target compa-ratio: the compa-ratio each rating is raised to. The increase is the gap from aligned base to mid × pay policy position × this target. Set 0% to give a rating no increase at all. A target above a grade's range max (max / mid) is cut at the max when 'Clip increases at range maximum' = Yes.
A27: Minimum increase: a floor for a rating, paid even when the person is already at or above the target. 0% = no floor. It does not apply at or above the range maximum or to ineligible staff, and it is limited by the per-person cap and, when the clip at max is on, by the headroom to the max.
A29: Compa-ratio zones: only for the Matrix sheet view | C29: Increases do not depend on zones. Zones only group people into the classic rating × compa-ratio grid on the Matrix sheet.
A30: Zone | B30: Lower bound (CR from)
A31: 1 | B31: 0
A32: 2 | B32: 0.9
A33: 3 | B33: 1
A34: 4 | B34: 1.1

Sheet Lists
A1: Effective from | B1: Minimum tenure, months | C1: No pay change in the last, months | D1: Increase cap | E1: Clip at range max
A2: 46327 | B2: 0 | C2: 0 | D2: No cap | E2: Yes
A3: 46357 | B3: 1 | C3: 1 | D3: 0.1 | E3: No
A4: 46388 | B4: 2 | C4: 2 | D4: 0.15
A5: 46419 | B5: 3 | C5: 3 | D5: 0.2
A6: 46447 | B6: 6 | C6: 6 | D6: 0.25
A7: 46478 | B7: 9 | C7: 9 | D7: 0.3
A8: 46508 | B8: 12 | C8: 12 | D8: 0.4
A9: 46539 | D9: 0.5
A10: 46569 | D10: 0.75
A11: 46600 | D11: 1
A12: 46631
A13: 46661
A14: 46692
A15: 46722
A16: 46753
A17: 46784
A18: 46813
A19: 46844
A20: 46874
A21: 46905
A22: 46935
A23: 46966
... A27: 47088

Sheet Bands
A1: Category | B1: Grade | C1: Range min | D1: Range mid | E1: Range max | F1: Lookup key
A2: Customer Support | B2: 3 | C2: 25700 | D2: 29500 | E2: 33400 | F2: =A2&"|"&B2 -> Customer Support|3
A3: Customer Support | B3: 4 | C3: 29800 | D3: 34300 | E3: 38700 | F3: =A3&"|"&B3 -> Customer Support|4
A4: Customer Support | B4: 5 | C4: 34500 | D4: 39700 | E4: 44900 | F4: =A4&"|"&B4 -> Customer Support|5
A5: Customer Support | B5: 6 | C5: 38300 | D5: 46000 | E5: 53600 | F5: =A5&"|"&B5 -> Customer Support|6
A6: Manufacturing | B6: 4 | C6: 30400 | D6: 35000 | E6: 39500 | F6: =A6&"|"&B6 -> Manufacturing|4
A7: Manufacturing | B7: 5 | C7: 35600 | D7: 40900 | E7: 46300 | F7: =A7&"|"&B7 -> Manufacturing|5
A8: Manufacturing | B8: 6 | C8: 39700 | D8: 47600 | E8: 55600 | F8: =A8&"|"&B8 -> Manufacturing|6
A9: Manufacturing | B9: 7 | C9: 46200 | D9: 55400 | E9: 64700 | F9: =A9&"|"&B9 -> Manufacturing|7
A10: Manufacturing | B10: 8 | C10: 53700 | D10: 64400 | E10: 75200 | F10: =A10&"|"&B10 -> Manufacturing|8
A11: Operations | B11: 5 | C11: 33700 | D11: 38800 | E11: 43800 | F11: =A11&"|"&B11 -> Operations|5
A12: Operations | B12: 6 | C12: 37000 | D12: 44400 | E12: 51800 | F12: =A12&"|"&B12 -> Operations|6
A13: Operations | B13: 7 | C13: 42300 | D13: 50800 | E13: 59200 | F13: =A13&"|"&B13 -> Operations|7
... A36: Legal | B36: 12 | C36: 76700 | D36: 99700 | E36: 122700 | F36: =A36&"|"&B36 -> Legal|12

Sheet Employees
A1: id | B1: category | C1: gender | D1: grade | E1: rating | F1: hire_date | G1: last_change_date | H1: base_salary | I1: bonus_pct | J1: fte
A2: E001 | B2: Engineering | C2: M | D2: 8 | E2: 4 | F2: 44433 | G2: 46270 | H2: 56987.18 | I2: 14.33 | J2: 1
A3: E002 | B3: Engineering | C3: M | D3: 9 | E3: 2 | F3: 43227 | G3: 46113 | H3: 65996.64 | I3: 13.38 | J3: 1
A4: E003 | B4: Engineering | C4: M | D4: 11 | E4: 3 | F4: 42168 | G4: 46113 | H4: 79747.78 | I4: 14.12 | J4: 1
A5: E004 | B5: Engineering | C5: M | D5: 10 | E5: 2 | F5: 43775 | G5: 46113 | H5: 73284.69 | I5: 11.99 | J5: 1
A6: E005 | B6: Engineering | C6: F | D6: 10 | E6: 4 | F6: 44067 | G6: 46113 | H6: 69538.46 | I6: 9.57 | J6: 1
A7: E006 | B7: Engineering | C7: M | D7: 9 | E7: 5 | F7: 44469 | G7: 46113 | H7: 60248.19 | I7: 10.4 | J7: 1
A8: E007 | B8: Engineering | C8: M | D8: 7 | E8: 5 | F8: 44725 | G8: 46113 | H8: 47983.14 | I8: 11.81 | J8: 1
A9: E008 | B9: Engineering | C9: M | D9: 11 | E9: 2 | F9: 44067 | G9: 46113 | H9: 79273.59 | I9: 9.24 | J9: 1
A10: E009 | B10: Engineering | C10: M | D10: 8 | E10: 3 | F10: 44323 | G10: 46113 | H10: 56597.91 | I10: 10.73 | J10: 1
A11: E010 | B11: Engineering | C11: M | D11: 10 | E11: 3 | F11: 42935 | G11: 46113 | H11: 75607.45 | I11: 11.99 | J11: 1
A12: E011 | B12: Engineering | C12: M | D12: 7 | E12: 2 | F12: 45455 | G12: 46113 | H12: 37697.15 | I12: 14.04 | J12: 1
A13: E012 | B13: Engineering | C13: M | D13: 9 | E13: 3 | F13: 43666 | G13: 46113 | H13: 60920.28 | I13: 12.28 | J13: 1
... A213: E212 | B213: Sales | C213: M | D213: 9 | E213: 3 | F213: 45127 | G213: 46113 | H213: 54620.08 | I213: 26 | J213: 1

Sheet Calc
A1: Step 0: Input | L1: Step 1: Range and total cash | R1: Step 2: Pay equity adjustment (unexplained gap closed in full) | AF1: Step 3: Eligibility | AI1: Step 4: Target salary | AO1: Step 5: Merit increase | BA1: Step 6: Cost (annual, FTE-weighted) | BN1: Step 6a: Target budget, the target % to every eligible person | BT1: Step 7: Total cash for the gap check
A2: Row number in the list. | B2: The n-th ID on Employees. | C2: Category of workers (same work or work of equal value); looked up by ID. | D2: F or M. | F2: 1 to 5. | H2: Last individual change. | I2: Annual gross base, full time; in Spain including the extra payments (pagas extra). | J2: Bonus as a share of base. | K2: 1 = full time. | L2: 0: no row for this category and grade on Bands; totals show #N/A until it is added. | M2: From Bands by category and grade. | P2: Years from hire to effective date. | Q2: Base plus bonus, full time. | R2: Helper sums for the regression on Categories. | W2: Rounded to the cent so that ranking compares exact values. | X2: Order by total cash within the category, for the median. | Y2: From Categories. | Z2: 1: woman below the category median, and the category has an unexplained gap against women. | AB2: Category amount shared in proportion to each shortfall. | AC2: Paid through base; the bonus follows the base. | AD2: Merit is computed from this base. | AE2: Amber flag, not an error. The adjustment is paid in full. The category's amount is shared in proportion to each woman's shortfall to the category median, and a category spans several grades, so her new pay can sit above her grade's range maximum. Worth a look: her grade, the range, or how the category is defined. | AF2: Complete months up to the effective date; −1 if hired after it. | AG2: −1 if the change is after the effective date. | AH2: 1: in the review. | AI2: Aligned base / range mid. | AJ2: Not used in the increase. Only places the person in a column of the Matrix sheet grid (rating × compa-ratio). | AK2: From the rating table. | AL2: Floor for the rating, paid even at or above target; see Inputs. | AM2: Mid × pay policy position × target compa-ratio. | AN2: 0 if already at or above target. | AO2: 0: 'No cap', empty or 0% on Inputs. | AP2: Largest increase for this person: the cap × their aligned base; 0 when there is no cap. | AR2: Gap to target, at least the minimum, never above the cap (if there is one). | AS2: At or above range max: no merit increase. | AT2: Already at or above max: increase set to 0, whatever the rule gave. | AU2: Range max − aligned base: the most an increase can add without leaving the range. | AV2: If 'Clip increases at range maximum' = Yes, an increase larger than the headroom is cut to the headroom, so new base = range max. | AW2: Annual full-time base increase. | AZ2: Flag. | BA2: (Annual base + bonus) × FTE. | BB2: Full rate up to the contribution ceiling, tiered rates above it (Inputs). | BH2: Bonus grows with base. | BI2: Extra employer contributions on the increase. | BM2: Aligned base of eligible staff, FTE-weighted: the denominator for the target %. | BN2: Aligned base × target %, full time. A benchmark, not a payout. | BP2: Each person's own bonus %. | BS2: Depends on where each person sits against the ceiling, so it is not a flat rate on the target base. | BV2: Helper sums for the regression after merit on Categories.
A4: No. | B4: ID | C4: Category | D4: Gender | E4: Grade | F4: Rating | G4: Hire date | H4: Last pay change | I4: Base salary | J4: Bonus % of base | K4: FTE | L4: Range found | M4: Range min | N4: Range mid | O4: Range max | P4: Tenure, years | Q4: Total cash | R4: grade² | S4: tenure² | T4: grade×tenure | U4: grade×cash | V4: tenure×cash | W4: Total cash, rounded | X4: Rank in category | Y4: Category median total cash | Z4: Receives adjustment | AA4: Shortfall to median | AB4: Adjustment, total cash | AC4: Adjustment, base | AD4: Aligned base | AE4: Above range max after equity adjustment | AF4: Months since hire | AG4: Months since change | AH4: Eligible | AI4: Compa-ratio | AJ4: Compa-ratio zone | AK4: Target compa-ratio for rating | AL4: Minimum increase | AM4: Target salary | AN4: Gap to target | AO4: Cap applies | AP4: Increase cap, € | AQ4: Minimum increase, € | AR4: Increase before range limits | AS4: At or above range max (red-circled) | AT4: After red-circle rule | AU4: Headroom to range max | AV4: After clip at max | AW4: Merit increase | AX4: Increase % | AY4: New base | AZ4: Below range min after review | BA4: Total cash before equity, at actual FTE | BB4: Employer contributions before equity | BC4: Total cash after equity, at actual FTE | BD4: Employer contributions after equity | BE4: Total cash after merit, at actual FTE | BF4: Employer contributions after merit | BG4: Equity: base | BH4: Equity: bonus | BI4: Equity: employer contributions | BJ4: Merit: base | BK4: Merit: bonus | BL4: Merit: employer contributions | BM4: Eligible base | BN4: Target increase | BO4: Target: base | BP4: Target: bonus | BQ4: Total cash at target, at actual FTE | BR4: Employer contributions at target | BS4: Target: employer contributions | BT4: Total cash after equity, full time | BU4: Total cash after merit, full time | BV4: grade×cash after merit | BW4: tenure×cash after merit
A5: =ROW()-4 -> 1 | B5: =INDEX(Employees!$A:$A,A5+1) -> E001 | C5: =INDEX(Employees!$A:$Z,MATCH(B5,Employees!$A:$A,0),MATCH("category",Employees!$1:$1,0)) -> Engineering | D5: =INDEX(Employees!$A:$Z,MATCH(B5,Employees!$A:$A,0),MATCH("gender",Employees!$1:$1,0)) -> M | E5: =INDEX(Employees!$A:$Z,MATCH(B5,Employees!$A:$A,0),MATCH("grade",Employees!$1:$1,0)) -> 8 | F5: =INDEX(Employees!$A:$Z,MATCH(B5,Employees!$A:$A,0),MATCH("rating",Employees!$1:$1,0)) -> 4 | G5: =INDEX(Employees!$A:$Z,MATCH(B5,Employees!$A:$A,0),MATCH("hire_date",Employees!$1:$1,0)) -> 44433 | H5: =INDEX(Employees!$A:$Z,MATCH(B5,Employees!$A:$A,0),MATCH("last_change_date",Employees!$1:$1,0)) -> 46270 | I5: =INDEX(Employees!$A:$Z,MATCH(B5,Employees!$A:$A,0),MATCH("base_salary",Employees!$1:$1,0)) -> 56987.18 | J5: =INDEX(Employees!$A:$Z,MATCH(B5,Employees!$A:$A,0),MATCH("bonus_pct",Employees!$1:$1,0))/100 -> 0.1433 | K5: =INDEX(Employees!$A:$Z,MATCH(B5,Employees!$A:$A,0),MATCH("fte",Employees!$1:$1,0)) -> 1 | L5: =IF(ISNA(MATCH(C5&"|"&E5,Bands!$F:$F,0)),0,1) -> 1 | M5: =INDEX(Bands!$C:$C,MATCH(C5&"|"&E5,Bands!$F:$F,0)) -> 47700 | N5: =INDEX(Bands!$D:$D,MATCH(C5&"|"&E5,Bands!$F:$F,0)) -> 57200 | O5: =INDEX(Bands!$E:$E,MATCH(C5&"|"&E5,Bands!$F:$F,0)) -> 66800 | P5: =(EffDate-G5)/365.25 -> 5.5989049 | Q5: =I5*(1+J5) -> 65153.443 | R5: =E5^2 -> 64 | S5: =P5^2 -> 31.347736 | T5: =E5*P5 -> 44.791239 | U5: =E5*Q5 -> 521227.54 | V5: =P5*Q5 -> 364787.93 | W5: =ROUND(Q5,2) -> 65153.44 | X5: =COUNTIFS($C:$C,C5,$W:$W,"<"&W5)+COUNTIFS($C:$C,C5,$W:$W,W5,$B:$B,"<"&B5)+1 -> 17 | Y5: =INDEX(Categories!$AH:$AH,MATCH(C5,Categories!$A:$A,0)) -> 71955.394 | Z5: =IF(AND(D5="F",Q5<Y5,INDEX(Categories!$AI:$AI,MATCH(C5,Categories!$A:$A,0))>0),1,0) -> 0 | AA5: =IF(Z5=1,Y5-Q5,0) -> 0 | AB5: =IF(Z5=1,INDEX(Categories!$AI:$AI,MATCH(C5,Categories!$A:$A,0))*AA5/INDEX(Categories!$AJ:$AJ,MATCH(C5,Categories!$A:$A,0)),0) -> 0 | AC5: =AB5/(1+J5) -> 0 | AD5: =I5+AC5 -> 56987.18 | AE5: =IF(AND(AC5>0,AD5>O5),1,0) -> 0 | AF5: =IF(G5>EffDate,-1,DATEDIF(G5,EffDate,"m")) -> 67 | AG5: =IF(H5>EffDate,-1,DATEDIF(H5,EffDate,"m")) -> 6 | AH5: =IF(AND(AF5>=MinMonthsHire,AG5>=MinMonthsChange),1,0) -> 1 | AI5: =AD5/N5 -> 0.99627937 | AJ5: =MATCH(AI5,Inputs!$B$31:$B$34,1) -> 2 | AK5: =INDEX(Inputs!$C$21:$C$25,MATCH(F5,Inputs!$A$21:$A$25,0)) -> 1.05 | AL5: =INDEX(Inputs!$D$21:$D$25,MATCH(F5,Inputs!$A$21:$A$25,0)) -> 0.01 | AM5: =N5*CompanyTarget*AK5 -> 60060 | AN5: =MAX(0,AM5-AD5) -> 3072.82 | AO5: =IF(AND(ISNUMBER(MaxIncrease),MaxIncrease>0),1,0) -> 1 | AP5: =IF(AO5=1,AD5*MaxIncrease,0) -> 17096.154 | AQ5: =AD5*AL5 -> 569.8718 | AR5: =IF(AK5=0,0,IF(AO5=1,MIN(MAX(AN5,AQ5),AP5),MAX(AN5,AQ5))) -> 3072.82 | AS5: =IF(AD5>=O5,1,0) -> 0 | AT5: =IF(AS5=1,0,AR5) -> 3072.82 | AU5: =MAX(0,O5-AD5) -> 9812.82 | AV5: =IF(ClipAtMax="No",AT5,MIN(AT5,AU5)) -> 3072.82 | AW5: =IF(AH5=1,AV5,0) -> 3072.82 | AX5: =IF(AD5>0,AW5/AD5,0) -> 0.05392125 | AY5: =AD5+AW5 -> 60060 | AZ5: =IF(AY5<M5,1,0) -> 0 | BA5: =Q5*K5 -> 65153.443 | BB5: =RateBelow*MIN(BA5,Ceiling)+AboveCeilingTier1*MIN(MAX(0,BA5-Ceiling),0.1*Ceiling)+AboveCeilingTier2*MIN(MAX(0,BA5-1.1*Ceiling),0.4*Ceiling)+AboveCeilingTier3*MAX(0,BA5-1.5*Ceiling) -> 19718.244 | BC5: =AD5*(1+J5)*K5 -> 65153.443 | BD5: =RateBelow*MIN(BC5,Ceiling)+AboveCeilingTier1*MIN(MAX(0,BC5-Ceiling),0.1*Ceiling)+AboveCeilingTier2*MIN(MAX(0,BC5-1.1*Ceiling),0.4*Ceiling)+AboveCeilingTier3*MAX(0,BC5-1.5*Ceiling) -> 19718.244 | BE5: =AY5*(1+J5)*K5 -> 68666.598 | BF5: =RateBelow*MIN(BE5,Ceiling)+AboveCeilingTier1*MIN(MAX(0,BE5-Ceiling),0.1*Ceiling)+AboveCeilingTier2*MIN(MAX(0,BE5-1.1*Ceiling),0.4*Ceiling)+AboveCeilingTier3*MAX(0,BE5-1.5*Ceiling) -> 19753.035 | BG5: =AC5*K5 -> 0 | BH5: =AC5*J5*K5 -> 0 | BI5: =BD5-BB5 -> 0 | BJ5: =AW5*K5 -> 3072.82 | BK5: =AW5*J5*K5 -> 440.33511 | BL5: =BF5-BD5 -> 34.790895 | BM5: =IF(AH5=1,AD5*K5,0) -> 56987.18 | BN5: =IF(AH5=1,AD5*PoolPct,0) -> 2279.4872 | BO5: =BN5*K5 -> 2279.4872 | BP5: =BN5*J5*K5 -> 326.65052 | BQ5: =(AD5+BN5)*(1+J5)*K5 -> 67759.581 | BR5: =RateBelow*MIN(BQ5,Ceiling)+AboveCeilingTier1*MIN(MAX(0,BQ5-Ceiling),0.1*Ceiling)+AboveCeilingTier2*MIN(MAX(0,BQ5-1.1*Ceiling),0.4*Ceiling)+AboveCeilingTier3*MAX(0,BQ5-1.5*Ceiling) -> 19743.602 | BS5: =BR5-BD5 -> 25.357915 | BT5: =AD5*(1+J5) -> 65153.443 | BU5: =AY5*(1+J5) -> 68666.598 | BV5: =E5*BU5 -> 549332.78 | BW5: =P5*BU5 -> 384457.75
A6: =ROW()-4 -> 2 | B6: =INDEX(Employees!$A:$A,A6+1) -> E002 | C6: =INDEX(Employees!$A:$Z,MATCH(B6,Employees!$A:$A,0),MATCH("category",Employees!$1:$1,0)) -> Engineering | D6: =INDEX(Employees!$A:$Z,MATCH(B6,Employees!$A:$A,0),MATCH("gender",Employees!$1:$1,0)) -> M | E6: =INDEX(Employees!$A:$Z,MATCH(B6,Employees!$A:$A,0),MATCH("grade",Employees!$1:$1,0)) -> 9 | F6: =INDEX(Employees!$A:$Z,MATCH(B6,Employees!$A:$A,0),MATCH("rating",Employees!$1:$1,0)) -> 2 | G6: =INDEX(Employees!$A:$Z,MATCH(B6,Employees!$A:$A,0),MATCH("hire_date",Employees!$1:$1,0)) -> 43227 | H6: =INDEX(Employees!$A:$Z,MATCH(B6,Employees!$A:$A,0),MATCH("last_change_date",Employees!$1:$1,0)) -> 46113 | I6: =INDEX(Employees!$A:$Z,MATCH(B6,Employees!$A:$A,0),MATCH("base_salary",Employees!$1:$1,0)) -> 65996.64 | J6: =INDEX(Employees!$A:$Z,MATCH(B6,Employees!$A:$A,0),MATCH("bonus_pct",Employees!$1:$1,0))/100 -> 0.1338 | K6: =INDEX(Employees!$A:$Z,MATCH(B6,Employees!$A:$A,0),MATCH("fte",Employees!$1:$1,0)) -> 1 | L6: =IF(ISNA(MATCH(C6&"|"&E6,Bands!$F:$F,0)),0,1) -> 1 | M6: =INDEX(Bands!$C:$C,MATCH(C6&"|"&E6,Bands!$F:$F,0)) -> 54500 | N6: =INDEX(Bands!$D:$D,MATCH(C6&"|"&E6,Bands!$F:$F,0)) -> 65400 | O6: =INDEX(Bands!$E:$E,MATCH(C6&"|"&E6,Bands!$F:$F,0)) -> 76300 | P6: =(EffDate-G6)/365.25 -> 8.9007529 | Q6: =I6*(1+J6) -> 74826.99 | R6: =E6^2 -> 81 | S6: =P6^2 -> 79.223402 | T6: =E6*P6 -> 80.106776 | U6: =E6*Q6 -> 673442.91 | V6: =P6*Q6 -> 666016.55 | W6: =ROUND(Q6,2) -> 74826.99 | X6: =COUNTIFS($C:$C,C6,$W:$W,"<"&W6)+COUNTIFS($C:$C,C6,$W:$W,W6,$B:$B,"<"&B6)+1 -> 25 | Y6: =INDEX(Categories!$AH:$AH,MATCH(C6,Categories!$A:$A,0)) -> 71955.394 | Z6: =IF(AND(D6="F",Q6<Y6,INDEX(Categories!$AI:$AI,MATCH(C6,Categories!$A:$A,0))>0),1,0) -> 0 | AA6: =IF(Z6=1,Y6-Q6,0) -> 0 | AB6: =IF(Z6=1,INDEX(Categories!$AI:$AI,MATCH(C6,Categories!$A:$A,0))*AA6/INDEX(Categories!$AJ:$AJ,MATCH(C6,Categories!$A:$A,0)),0) -> 0 | AC6: =AB6/(1+J6) -> 0 | AD6: =I6+AC6 -> 65996.64 | AE6: =IF(AND(AC6>0,AD6>O6),1,0) -> 0 | AF6: =IF(G6>EffDate,-1,DATEDIF(G6,EffDate,"m")) -> 106 | AG6: =IF(H6>EffDate,-1,DATEDIF(H6,EffDate,"m")) -> 12 | AH6: =IF(AND(AF6>=MinMonthsHire,AG6>=MinMonthsChange),1,0) -> 1 | AI6: =AD6/N6 -> 1.0091229 | AJ6: =MATCH(AI6,Inputs!$B$31:$B$34,1) -> 3 | AK6: =INDEX(Inputs!$C$21:$C$25,MATCH(F6,Inputs!$A$21:$A$25,0)) -> 0.95 | AL6: =INDEX(Inputs!$D$21:$D$25,MATCH(F6,Inputs!$A$21:$A$25,0)) -> 0 | AM6: =N6*CompanyTarget*AK6 -> 62130 | AN6: =MAX(0,AM6-AD6) -> 0 | AO6: =IF(AND(ISNUMBER(MaxIncrease),MaxIncrease>0),1,0) -> 1 | AP6: =IF(AO6=1,AD6*MaxIncrease,0) -> 19798.992 | AQ6: =AD6*AL6 -> 0 | AR6: =IF(AK6=0,0,IF(AO6=1,MIN(MAX(AN6,AQ6),AP6),MAX(AN6,AQ6))) -> 0 | AS6: =IF(AD6>=O6,1,0) -> 0 | AT6: =IF(AS6=1,0,AR6) -> 0 | AU6: =MAX(0,O6-AD6) -> 10303.36 | AV6: =IF(ClipAtMax="No",AT6,MIN(AT6,AU6)) -> 0 | AW6: =IF(AH6=1,AV6,0) -> 0 | AX6: =IF(AD6>0,AW6/AD6,0) -> 0 | AY6: =AD6+AW6 -> 65996.64 | AZ6: =IF(AY6<M6,1,0) -> 0 | BA6: =Q6*K6 -> 74826.99 | BB6: =RateBelow*MIN(BA6,Ceiling)+AboveCeilingTier1*MIN(MAX(0,BA6-Ceiling),0.1*Ceiling)+AboveCeilingTier2*MIN(MAX(0,BA6-1.1*Ceiling),0.4*Ceiling)+AboveCeilingTier3*MAX(0,BA6-1.5*Ceiling) -> 19817.103 | BC6: =AD6*(1+J6)*K6 -> 74826.99 | BD6: =RateBelow*MIN(BC6,Ceiling)+AboveCeilingTier1*MIN(MAX(0,BC6-Ceiling),0.1*Ceiling)+AboveCeilingTier2*MIN(MAX(0,BC6-1.1*Ceiling),0.4*Ceiling)+AboveCeilingTier3*MAX(0,BC6-1.5*Ceiling) -> 19817.103 | BE6: =AY6*(1+J6)*K6 -> 74826.99 | BF6: =RateBelow*MIN(BE6,Ceiling)+AboveCeilingTier1*MIN(MAX(0,BE6-Ceiling),0.1*Ceiling)+AboveCeilingTier2*MIN(MAX(0,BE6-1.1*Ceiling),0.4*Ceiling)+AboveCeilingTier3*MAX(0,BE6-1.5*Ceiling) -> 19817.103 | BG6: =AC6*K6 -> 0 | BH6: =AC6*J6*K6 -> 0 | BI6: =BD6-BB6 -> 0 | BJ6: =AW6*K6 -> 0 | BK6: =AW6*J6*K6 -> 0 | BL6: =BF6-BD6 -> 0 | BM6: =IF(AH6=1,AD6*K6,0) -> 65996.64 | BN6: =IF(AH6=1,AD6*PoolPct,0) -> 2639.8656 | BO6: =BN6*K6 -> 2639.8656 | BP6: =BN6*J6*K6 -> 353.21402 | BQ6: =(AD6+BN6)*(1+J6)*K6 -> 77820.07 | BR6: =RateBelow*MIN(BQ6,Ceiling)+AboveCeilingTier1*MIN(MAX(0,BQ6-Ceiling),0.1*Ceiling)+AboveCeilingTier2*MIN(MAX(0,BQ6-1.1*Ceiling),0.4*Ceiling)+AboveCeilingTier3*MAX(0,BQ6-1.5*Ceiling) -> 19848.231 | BS6: =BR6-BD6 -> 31.128028 | BT6: =AD6*(1+J6) -> 74826.99 | BU6: =AY6*(1+J6) -> 74826.99 | BV6: =E6*BU6 -> 673442.91 | BW6: =P6*BU6 -> 666016.55
A7: =ROW()-4 -> 3 | B7: =INDEX(Employees!$A:$A,A7+1) -> E003 | C7: =INDEX(Employees!$A:$Z,MATCH(B7,Employees!$A:$A,0),MATCH("category",Employees!$1:$1,0)) -> Engineering | D7: =INDEX(Employees!$A:$Z,MATCH(B7,Employees!$A:$A,0),MATCH("gender",Employees!$1:$1,0)) -> M | E7: =INDEX(Employees!$A:$Z,MATCH(B7,Employees!$A:$A,0),MATCH("grade",Employees!$1:$1,0)) -> 11 | F7: =INDEX(Employees!$A:$Z,MATCH(B7,Employees!$A:$A,0),MATCH("rating",Employees!$1:$1,0)) -> 3 | G7: =INDEX(Employees!$A:$Z,MATCH(B7,Employees!$A:$A,0),MATCH("hire_date",Employees!$1:$1,0)) -> 42168 | H7: =INDEX(Employees!$A:$Z,MATCH(B7,Employees!$A:$A,0),MATCH("last_change_date",Employees!$1:$1,0)) -> 46113 | I7: =INDEX(Employees!$A:$Z,MATCH(B7,Employees!$A:$A,0),MATCH("base_salary",Employees!$1:$1,0)) -> 79747.78 | J7: =INDEX(Employees!$A:$Z,MATCH(B7,Employees!$A:$A,0),MATCH("bonus_pct",Employees!$1:$1,0))/100 -> 0.1412 | K7: =INDEX(Employees!$A:$Z,MATCH(B7,Employees!$A:$A,0),MATCH("fte",Employees!$1:$1,0)) -> 1 | L7: =IF(ISNA(MATCH(C7&"|"&E7,Bands!$F:$F,0)),0,1) -> 1 | M7: =INDEX(Bands!$C:$C,MATCH(C7&"|"&E7,Bands!$F:$F,0)) -> 68400 | N7: =INDEX(Bands!$D:$D,MATCH(C7&"|"&E7,Bands!$F:$F,0)) -> 85500 | O7: =INDEX(Bands!$E:$E,MATCH(C7&"|"&E7,Bands!$F:$F,0)) -> 102600 | P7: =(EffDate-G7)/365.25 -> 11.800137 | Q7: =I7*(1+J7) -> 91008.167 | R7: =E7^2 -> 121 | S7: =P7^2 -> 139.24323 | T7: =E7*P7 -> 129.80151 | U7: =E7*Q7 -> 1001089.8 | V7: =P7*Q7 -> 1073908.8 | W7: =ROUND(Q7,2) -> 91008.17 | X7: =COUNTIFS($C:$C,C7,$W:$W,"<"&W7)+COUNTIFS($C:$C,C7,$W:$W,W7,$B:$B,"<"&B7)+1 -> 40 | Y7: =INDEX(Categories!$AH:$AH,MATCH(C7,Categories!$A:$A,0)) -> 71955.394 | Z7: =IF(AND(D7="F",Q7<Y7,INDEX(Categories!$AI:$AI,MATCH(C7,Categories!$A:$A,0))>0),1,0) -> 0 | AA7: =IF(Z7=1,Y7-Q7,0) -> 0 | AB7: =IF(Z7=1,INDEX(Categories!$AI:$AI,MATCH(C7,Categories!$A:$A,0))*AA7/INDEX(Categories!$AJ:$AJ,MATCH(C7,Categories!$A:$A,0)),0) -> 0 | AC7: =AB7/(1+J7) -> 0 | AD7: =I7+AC7 -> 79747.78 | AE7: =IF(AND(AC7>0,AD7>O7),1,0) -> 0 | AF7: =IF(G7>EffDate,-1,DATEDIF(G7,EffDate,"m")) -> 141 | AG7: =IF(H7>EffDate,-1,DATEDIF(H7,EffDate,"m")) -> 12 | AH7: =IF(AND(AF7>=MinMonthsHire,AG7>=MinMonthsChange),1,0) -> 1 | AI7: =AD7/N7 -> 0.93272257 | AJ7: =MATCH(AI7,Inputs!$B$31:$B$34,1) -> 2 | AK7: =INDEX(Inputs!$C$21:$C$25,MATCH(F7,Inputs!$A$21:$A$25,0)) -> 1 | AL7: =INDEX(Inputs!$D$21:$D$25,MATCH(F7,Inputs!$A$21:$A$25,0)) -> 0 | AM7: =N7*CompanyTarget*AK7 -> 85500 | AN7: =MAX(0,AM7-AD7) -> 5752.22 | AO7: =IF(AND(ISNUMBER(MaxIncrease),MaxIncrease>0),1,0) -> 1 | AP7: =IF(AO7=1,AD7*MaxIncrease,0) -> 23924.334 | AQ7: =AD7*AL7 -> 0 | AR7: =IF(AK7=0,0,IF(AO7=1,MIN(MAX(AN7,AQ7),AP7),MAX(AN7,AQ7))) -> 5752.22 | AS7: =IF(AD7>=O7,1,0) -> 0 | AT7: =IF(AS7=1,0,AR7) -> 5752.22 | AU7: =MAX(0,O7-AD7) -> 22852.22 | AV7: =IF(ClipAtMax="No",AT7,MIN(AT7,AU7)) -> 5752.22 | AW7: =IF(AH7=1,AV7,0) -> 5752.22 | AX7: =IF(AD7>0,AW7/AD7,0) -> 0.072130158 | AY7: =AD7+AW7 -> 85500 | AZ7: =IF(AY7<M7,1,0) -> 0 | BA7: =Q7*K7 -> 91008.167 | BB7: =RateBelow*MIN(BA7,Ceiling)+AboveCeilingTier1*MIN(MAX(0,BA7-Ceiling),0.1*Ceiling)+AboveCeilingTier2*MIN(MAX(0,BA7-1.1*Ceiling),0.4*Ceiling)+AboveCeilingTier3*MAX(0,BA7-1.5*Ceiling) -> 19985.388 | BC7: =AD7*(1+J7)*K7 -> 91008.167 | BD7: =RateBelow*MIN(BC7,Ceiling)+AboveCeilingTier1*MIN(MAX(0,BC7-Ceiling),0.1*Ceiling)+AboveCeilingTier2*MIN(MAX(0,BC7-1.1*Ceiling),0.4*Ceiling)+AboveCeilingTier3*MAX(0,BC7-1.5*Ceiling) -> 19985.388 | BE7: =AY7*(1+J7)*K7 -> 97572.6 | BF7: =RateBelow*MIN(BE7,Ceiling)+AboveCeilingTier1*MIN(MAX(0,BE7-Ceiling),0.1*Ceiling)+AboveCeilingTier2*MIN(MAX(0,BE7-1.1*Ceiling),0.4*Ceiling)+AboveCeilingTier3*MAX(0,BE7-1.5*Ceiling) -> 20064.01 | BG7: =AC7*K7 -> 0 | BH7: =AC7*J7*K7 -> 0 | BI7: =BD7-BB7 -> 0 | BJ7: =AW7*K7 -> 5752.22 | BK7: =AW7*J7*K7 -> 812.21346 | BL7: =BF7-BD7 -> 78.621908 | BM7: =IF(AH7=1,AD7*K7,0) -> 79747.78 | BN7: =IF(AH7=1,AD7*PoolPct,0) -> 3189.9112 | BO7: =BN7*K7 -> 3189.9112 | BP7: =BN7*J7*K7 -> 450.41546 | BQ7: =(AD7+BN7)*(1+J7)*K7 -> 94648.493 | BR7: =RateBelow*MIN(BQ7,Ceiling)+AboveCeilingTier1*MIN(MAX(0,BQ7-Ceiling),0.1*Ceiling)+AboveCeilingTier2*MIN(MAX(0,BQ7-1.1*Ceiling),0.4*Ceiling)+AboveCeilingTier3*MAX(0,BQ7-1.5*Ceiling) -> 20028.335 | BS7: =BR7-BD7 -> 42.947805 | BT7: =AD7*(1+J7) -> 91008.167 | BU7: =AY7*(1+J7) -> 97572.6 | BV7: =E7*BU7 -> 1073298.6 | BW7: =P7*BU7 -> 1151370
A8: =ROW()-4 -> 4 | B8: =INDEX(Employees!$A:$A,A8+1) -> E004 | C8: =INDEX(Employees!$A:$Z,MATCH(B8,Employees!$A:$A,0),MATCH("category",Employees!$1:$1,0)) -> Engineering | D8: =INDEX(Employees!$A:$Z,MATCH(B8,Employees!$A:$A,0),MATCH("gender",Employees!$1:$1,0)) -> M | E8: =INDEX(Employees!$A:$Z,MATCH(B8,Employees!$A:$A,0),MATCH("grade",Employees!$1:$1,0)) -> 10 | F8: =INDEX(Employees!$A:$Z,MATCH(B8,Employees!$A:$A,0),MATCH("rating",Employees!$1:$1,0)) -> 2 | G8: =INDEX(Employees!$A:$Z,MATCH(B8,Employees!$A:$A,0),MATCH("hire_date",Employees!$1:$1,0)) -> 43775 | H8: =INDEX(Employees!$A:$Z,MATCH(B8,Employees!$A:$A,0),MATCH("last_change_date",Employees!$1:$1,0)) -> 46113 | I8: =INDEX(Employees!$A:$Z,MATCH(B8,Employees!$A:$A,0),MATCH("base_salary",Employees!$1:$1,0)) -> 73284.69 | J8: =INDEX(Employees!$A:$Z,MATCH(B8,Employees!$A:$A,0),MATCH("bonus_pct",Employees!$1:$1,0))/100 -> 0.1199 | K8: =INDEX(Employees!$A:$Z,MATCH(B8,Employees!$A:$A,0),MATCH("fte",Employees!$1:$1,0)) -> 1 | L8: =IF(ISNA(MATCH(C8&"|"&E8,Bands!$F:$F,0)),0,1) -> 1 | M8: =INDEX(Bands!$C:$C,MATCH(C8&"|"&E8,Bands!$F:$F,0)) -> 59800 | N8: =INDEX(Bands!$D:$D,MATCH(C8&"|"&E8,Bands!$F:$F,0)) -> 74800 | O8: =INDEX(Bands!$E:$E,MATCH(C8&"|"&E8,Bands!$F:$F,0)) -> 89700 | P8: =(EffDate-G8)/365.25 -> 7.4004107 | Q8: =I8*(1+J8) -> 82071.524 | R8: =E8^2 -> 100 | S8: =P8^2 -> 54.766078 | T8: =E8*P8 -> 74.004107 | U8: =E8*Q8 -> 820715.24 | V8: =P8*Q8 -> 607362.98 | W8: =ROUND(Q8,2) -> 82071.52 | X8: =COUNTIFS($C:$C,C8,$W:$W,"<"&W8)+COUNTIFS($C:$C,C8,$W:$W,W8,$B:$B,"<"&B8)+1 -> 33 | Y8: =INDEX(Categories!$AH:$AH,MATCH(C8,Categories!$A:$A,0)) -> 71955.394 | Z8: =IF(AND(D8="F",Q8<Y8,INDEX(Categories!$AI:$AI,MATCH(C8,Categories!$A:$A,0))>0),1,0) -> 0 | AA8: =IF(Z8=1,Y8-Q8,0) -> 0 | AB8: =IF(Z8=1,INDEX(Categories!$AI:$AI,MATCH(C8,Categories!$A:$A,0))*AA8/INDEX(Categories!$AJ:$AJ,MATCH(C8,Categories!$A:$A,0)),0) -> 0 | AC8: =AB8/(1+J8) -> 0 | AD8: =I8+AC8 -> 73284.69 | AE8: =IF(AND(AC8>0,AD8>O8),1,0) -> 0 | AF8: =IF(G8>EffDate,-1,DATEDIF(G8,EffDate,"m")) -> 88 | AG8: =IF(H8>EffDate,-1,DATEDIF(H8,EffDate,"m")) -> 12 | AH8: =IF(AND(AF8>=MinMonthsHire,AG8>=MinMonthsChange),1,0) -> 1 | AI8: =AD8/N8 -> 0.97974184 | AJ8: =MATCH(AI8,Inputs!$B$31:$B$34,1) -> 2 | AK8: =INDEX(Inputs!$C$21:$C$25,MATCH(F8,Inputs!$A$21:$A$25,0)) -> 0.95 | AL8: =INDEX(Inputs!$D$21:$D$25,MATCH(F8,Inputs!$A$21:$A$25,0)) -> 0 | AM8: =N8*CompanyTarget*AK8 -> 71060 | AN8: =MAX(0,AM8-AD8) -> 0 | AO8: =IF(AND(ISNUMBER(MaxIncrease),MaxIncrease>0),1,0) -> 1 | AP8: =IF(AO8=1,AD8*MaxIncrease,0) -> 21985.407 | AQ8: =AD8*AL8 -> 0 | AR8: =IF(AK8=0,0,IF(AO8=1,MIN(MAX(AN8,AQ8),AP8),MAX(AN8,AQ8))) -> 0 | AS8: =IF(AD8>=O8,1,0) -> 0 | AT8: =IF(AS8=1,0,AR8) -> 0 | AU8: =MAX(0,O8-AD8) -> 16415.31 | AV8: =IF(ClipAtMax="No",AT8,MIN(AT8,AU8)) -> 0 | AW8: =IF(AH8=1,AV8,0) -> 0 | AX8: =IF(AD8>0,AW8/AD8,0) -> 0 | AY8: =AD8+AW8 -> 73284.69 | AZ8: =IF(AY8<M8,1,0) -> 0 | BA8: =Q8*K8 -> 82071.524 | BB8: =RateBelow*MIN(BA8,Ceiling)+AboveCeilingTier1*MIN(MAX(0,BA8-Ceiling),0.1*Ceiling)+AboveCeilingTier2*MIN(MAX(0,BA8-1.1*Ceiling),0.4*Ceiling)+AboveCeilingTier3*MAX(0,BA8-1.5*Ceiling) -> 19892.447 | BC8: =AD8*(1+J8)*K8 -> 82071.524 | BD8: =RateBelow*MIN(BC8,Ceiling)+AboveCeilingTier1*MIN(MAX(0,BC8-Ceiling),0.1*Ceiling)+AboveCeilingTier2*MIN(MAX(0,BC8-1.1*Ceiling),0.4*Ceiling)+AboveCeilingTier3*MAX(0,BC8-1.5*Ceiling) -> 19892.447 | BE8: =AY8*(1+J8)*K8 -> 82071.524 | BF8: =RateBelow*MIN(BE8,Ceiling)+AboveCeilingTier1*MIN(MAX(0,BE8-Ceiling),0.1*Ceiling)+AboveCeilingTier2*MIN(MAX(0,BE8-1.1*Ceiling),0.4*Ceiling)+AboveCeilingTier3*MAX(0,BE8-1.5*Ceiling) -> 19892.447 | BG8: =AC8*K8 -> 0 | BH8: =AC8*J8*K8 -> 0 | BI8: =BD8-BB8 -> 0 | BJ8: =AW8*K8 -> 0 | BK8: =AW8*J8*K8 -> 0 | BL8: =BF8-BD8 -> 0 | BM8: =IF(AH8=1,AD8*K8,0) -> 73284.69 | BN8: =IF(AH8=1,AD8*PoolPct,0) -> 2931.3876 | BO8: =BN8*K8 -> 2931.3876 | BP8: =BN8*J8*K8 -> 351.47337 | BQ8: =(AD8+BN8)*(1+J8)*K8 -> 85354.385 | BR8: =RateBelow*MIN(BQ8,Ceiling)+AboveCeilingTier1*MIN(MAX(0,BQ8-Ceiling),0.1*Ceiling)+AboveCeilingTier2*MIN(MAX(0,BQ8-1.1*Ceiling),0.4*Ceiling)+AboveCeilingTier3*MAX(0,BQ8-1.5*Ceiling) -> 19926.588 | BS8: =BR8-BD8 -> 34.141754 | BT8: =AD8*(1+J8) -> 82071.524 | BU8: =AY8*(1+J8) -> 82071.524 | BV8: =E8*BU8 -> 820715.24 | BW8: =P8*BU8 -> 607362.98
A9: =ROW()-4 -> 5 | B9: =INDEX(Employees!$A:$A,A9+1) -> E005 | C9: =INDEX(Employees!$A:$Z,MATCH(B9,Employees!$A:$A,0),MATCH("category",Employees!$1:$1,0)) -> Engineering | D9: =INDEX(Employees!$A:$Z,MATCH(B9,Employees!$A:$A,0),MATCH("gender",Employees!$1:$1,0)) -> F | E9: =INDEX(Employees!$A:$Z,MATCH(B9,Employees!$A:$A,0),MATCH("grade",Employees!$1:$1,0)) -> 10 | F9: =INDEX(Employees!$A:$Z,MATCH(B9,Employees!$A:$A,0),MATCH("rating",Employees!$1:$1,0)) -> 4 | G9: =INDEX(Employees!$A:$Z,MATCH(B9,Employees!$A:$A,0),MATCH("hire_date",Employees!$1:$1,0)) -> 44067 | H9: =INDEX(Employees!$A:$Z,MATCH(B9,Employees!$A:$A,0),MATCH("last_change_date",Employees!$1:$1,0)) -> 46113 | I9: =INDEX(Employees!$A:$Z,MATCH(B9,Employees!$A:$A,0),MATCH("base_salary",Employees!$1:$1,0)) -> 69538.46 | J9: =INDEX(Employees!$A:$Z,MATCH(B9,Employees!$A:$A,0),MATCH("bonus_pct",Employees!$1:$1,0))/100 -> 0.0957 | K9: =INDEX(Employees!$A:$Z,MATCH(B9,Employees!$A:$A,0),MATCH("fte",Employees!$1:$1,0)) -> 1 | L9: =IF(ISNA(MATCH(C9&"|"&E9,Bands!$F:$F,0)),0,1) -> 1 | M9: =INDEX(Bands!$C:$C,MATCH(C9&"|"&E9,Bands!$F:$F,0)) -> 59800 | N9: =INDEX(Bands!$D:$D,MATCH(C9&"|"&E9,Bands!$F:$F,0)) -> 74800 | O9: =INDEX(Bands!$E:$E,MATCH(C9&"|"&E9,Bands!$F:$F,0)) -> 89700 | P9: =(EffDate-G9)/365.25 -> 6.6009582 | Q9: =I9*(1+J9) -> 76193.291 | R9: =E9^2 -> 100 | S9: =P9^2 -> 43.57265 | T9: =E9*P9 -> 66.009582 | U9: =E9*Q9 -> 761932.91 | V9: =P9*Q9 -> 502948.73 | W9: =ROUND(Q9,2) -> 76193.29 | X9: =COUNTIFS($C:$C,C9,$W:$W,"<"&W9)+COUNTIFS($C:$C,C9,$W:$W,W9,$B:$B,"<"&B9)+1 -> 26 | Y9: =INDEX(Categories!$AH:$AH,MATCH(C9,Categories!$A:$A,0)) -> 71955.394 | Z9: =IF(AND(D9="F",Q9<Y9,INDEX(Categories!$AI:$AI,MATCH(C9,Categories!$A:$A,0))>0),1,0) -> 0 | AA9: =IF(Z9=1,Y9-Q9,0) -> 0 | AB9: =IF(Z9=1,INDEX(Categories!$AI:$AI,MATCH(C9,Categories!$A:$A,0))*AA9/INDEX(Categories!$AJ:$AJ,MATCH(C9,Categories!$A:$A,0)),0) -> 0 | AC9: =AB9/(1+J9) -> 0 | AD9: =I9+AC9 -> 69538.46 | AE9: =IF(AND(AC9>0,AD9>O9),1,0) -> 0 | AF9: =IF(G9>EffDate,-1,DATEDIF(G9,EffDate,"m")) -> 79 | AG9: =IF(H9>EffDate,-1,DATEDIF(H9,EffDate,"m")) -> 12 | AH9: =IF(AND(AF9>=MinMonthsHire,AG9>=MinMonthsChange),1,0) -> 1 | AI9: =AD9/N9 -> 0.92965856 | AJ9: =MATCH(AI9,Inputs!$B$31:$B$34,1) -> 2 | AK9: =INDEX(Inputs!$C$21:$C$25,MATCH(F9,Inputs!$A$21:$A$25,0)) -> 1.05 | AL9: =INDEX(Inputs!$D$21:$D$25,MATCH(F9,Inputs!$A$21:$A$25,0)) -> 0.01 | AM9: =N9*CompanyTarget*AK9 -> 78540 | AN9: =MAX(0,AM9-AD9) -> 9001.54 | AO9: =IF(AND(ISNUMBER(MaxIncrease),MaxIncrease>0),1,0) -> 1 | AP9: =IF(AO9=1,AD9*MaxIncrease,0) -> 20861.538 | AQ9: =AD9*AL9 -> 695.3846 | AR9: =IF(AK9=0,0,IF(AO9=1,MIN(MAX(AN9,AQ9),AP9),MAX(AN9,AQ9))) -> 9001.54 | AS9: =IF(AD9>=O9,1,0) -> 0 | AT9: =IF(AS9=1,0,AR9) -> 9001.54 | AU9: =MAX(0,O9-AD9) -> 20161.54 | AV9: =IF(ClipAtMax="No",AT9,MIN(AT9,AU9)) -> 9001.54 | AW9: =IF(AH9=1,AV9,0) -> 9001.54 | AX9: =IF(AD9>0,AW9/AD9,0) -> 0.12944693 | AY9: =AD9+AW9 -> 78540 | AZ9: =IF(AY9<M9,1,0) -> 0 | BA9: =Q9*K9 -> 76193.291 | BB9: =RateBelow*MIN(BA9,Ceiling)+AboveCeilingTier1*MIN(MAX(0,BA9-Ceiling),0.1*Ceiling)+AboveCeilingTier2*MIN(MAX(0,BA9-1.1*Ceiling),0.4*Ceiling)+AboveCeilingTier3*MAX(0,BA9-1.5*Ceiling) -> 19831.313 | BC9: =AD9*(1+J9)*K9 -> 76193.291 | BD9: =RateBelow*MIN(BC9,Ceiling)+AboveCeilingTier1*MIN(MAX(0,BC9-Ceiling),0.1*Ceiling)+AboveCeilingTier2*MIN(MAX(0,BC9-1.1*Ceiling),0.4*Ceiling)+AboveCeilingTier3*MAX(0,BC9-1.5*Ceiling) -> 19831.313 | BE9: =AY9*(1+J9)*K9 -> 86056.278 | BF9: =RateBelow*MIN(BE9,Ceiling)+AboveCeilingTier1*MIN(MAX(0,BE9-Ceiling),0.1*Ceiling)+AboveCeilingTier2*MIN(MAX(0,BE9-1.1*Ceiling),0.4*Ceiling)+AboveCeilingTier3*MAX(0,BE9-1.5*Ceiling) -> 19933.888 | BG9: =AC9*K9 -> 0 | BH9: =AC9*J9*K9 -> 0 | BI9: =BD9-BB9 -> 0 | BJ9: =AW9*K9 -> 9001.54 | BK9: =AW9*J9*K9 -> 861.44738 | BL9: =BF9-BD9 -> 102.57507 | BM9: =IF(AH9=1,AD9*K9,0) -> 69538.46 | BN9: =IF(AH9=1,AD9*PoolPct,0) -> 2781.5384 | BO9: =BN9*K9 -> 2781.5384 | BP9: =BN9*J9*K9 -> 266.19322 | BQ9: =(AD9+BN9)*(1+J9)*K9 -> 79241.022 | BR9: =RateBelow*MIN(BQ9,Ceiling)+AboveCeilingTier1*MIN(MAX(0,BQ9-Ceiling),0.1*Ceiling)+AboveCeilingTier2*MIN(MAX(0,BQ9-1.1*Ceiling),0.4*Ceiling)+AboveCeilingTier3*MAX(0,BQ9-1.5*Ceiling) -> 19863.009 | BS9: =BR9-BD9 -> 31.696409 | BT9: =AD9*(1+J9) -> 76193.291 | BU9: =AY9*(1+J9) -> 86056.278 | BV9: =E9*BU9 -> 860562.78 | BW9: =P9*BU9 -> 568053.9
A10: =ROW()-4 -> 6 | B10: =INDEX(Employees!$A:$A,A10+1) -> E006 | C10: =INDEX(Employees!$A:$Z,MATCH(B10,Employees!$A:$A,0),MATCH("category",Employees!$1:$1,0)) -> Engineering | D10: =INDEX(Employees!$A:$Z,MATCH(B10,Employees!$A:$A,0),MATCH("gender",Employees!$1:$1,0)) -> M | E10: =INDEX(Employees!$A:$Z,MATCH(B10,Employees!$A:$A,0),MATCH("grade",Employees!$1:$1,0)) -> 9 | F10: =INDEX(Employees!$A:$Z,MATCH(B10,Employees!$A:$A,0),MATCH("rating",Employees!$1:$1,0)) -> 5 | G10: =INDEX(Employees!$A:$Z,MATCH(B10,Employees!$A:$A,0),MATCH("hire_date",Employees!$1:$1,0)) -> 44469 | H10: =INDEX(Employees!$A:$Z,MATCH(B10,Employees!$A:$A,0),MATCH("last_change_date",Employees!$1:$1,0)) -> 46113 | I10: =INDEX(Employees!$A:$Z,MATCH(B10,Employees!$A:$A,0),MATCH("base_salary",Employees!$1:$1,0)) -> 60248.19 | J10: =INDEX(Employees!$A:$Z,MATCH(B10,Employees!$A:$A,0),MATCH("bonus_pct",Employees!$1:$1,0))/100 -> 0.104 | K10: =INDEX(Employees!$A:$Z,MATCH(B10,Employees!$A:$A,0),MATCH("fte",Employees!$1:$1,0)) -> 1 | L10: =IF(ISNA(MATCH(C10&"|"&E10,Bands!$F:$F,0)),0,1) -> 1 | M10: =INDEX(Bands!$C:$C,MATCH(C10&"|"&E10,Bands!$F:$F,0)) -> 54500 | N10: =INDEX(Bands!$D:$D,MATCH(C10&"|"&E10,Bands!$F:$F,0)) -> 65400 | O10: =INDEX(Bands!$E:$E,MATCH(C10&"|"&E10,Bands!$F:$F,0)) -> 76300 | P10: =(EffDate-G10)/365.25 -> 5.5003422 | Q10: =I10*(1+J10) -> 66514.002 | R10: =E10^2 -> 81 | S10: =P10^2 -> 30.253765 | T10: =E10*P10 -> 49.50308 | U10: =E10*Q10 -> 598626.02 | V10: =P10*Q10 -> 365849.77 | W10: =ROUND(Q10,2) -> 66514 | X10: =COUNTIFS($C:$C,C10,$W:$W,"<"&W10)+COUNTIFS($C:$C,C10,$W:$W,W10,$B:$B,"<"&B10)+1 -> 18 | Y10: =INDEX(Categories!$AH:$AH,MATCH(C10,Categories!$A:$A,0)) -> 71955.394 | Z10: =IF(AND(D10="F",Q10<Y10,INDEX(Categories!$AI:$AI,MATCH(C10,Categories!$A:$A,0))>0),1,0) -> 0 | AA10: =IF(Z10=1,Y10-Q10,0) -> 0 | AB10: =IF(Z10=1,INDEX(Categories!$AI:$AI,MATCH(C10,Categories!$A:$A,0))*AA10/INDEX(Categories!$AJ:$AJ,MATCH(C10,Categories!$A:$A,0)),0) -> 0 | AC10: =AB10/(1+J10) -> 0 | AD10: =I10+AC10 -> 60248.19 | AE10: =IF(AND(AC10>0,AD10>O10),1,0) -> 0 | AF10: =IF(G10>EffDate,-1,DATEDIF(G10,EffDate,"m")) -> 66 | AG10: =IF(H10>EffDate,-1,DATEDIF(H10,EffDate,"m")) -> 12 | AH10: =IF(AND(AF10>=MinMonthsHire,AG10>=MinMonthsChange),1,0) -> 1 | AI10: =AD10/N10 -> 0.92122615 | AJ10: =MATCH(AI10,Inputs!$B$31:$B$34,1) -> 2 | AK10: =INDEX(Inputs!$C$21:$C$25,MATCH(F10,Inputs!$A$21:$A$25,0)) -> 1.1 | AL10: =INDEX(Inputs!$D$21:$D$25,MATCH(F10,Inputs!$A$21:$A$25,0)) -> 0.02 | AM10: =N10*CompanyTarget*AK10 -> 71940 | AN10: =MAX(0,AM10-AD10) -> 11691.81 | AO10: =IF(AND(ISNUMBER(MaxIncrease),MaxIncrease>0),1,0) -> 1 | AP10: =IF(AO10=1,AD10*MaxIncrease,0) -> 18074.457 | AQ10: =AD10*AL10 -> 1204.9638 | AR10: =IF(AK10=0,0,IF(AO10=1,MIN(MAX(AN10,AQ10),AP10),MAX(AN10,AQ10))) -> 11691.81 | AS10: =IF(AD10>=O10,1,0) -> 0 | AT10: =IF(AS10=1,0,AR10) -> 11691.81 | AU10: =MAX(0,O10-AD10) -> 16051.81 | AV10: =IF(ClipAtMax="No",AT10,MIN(AT10,AU10)) -> 11691.81 | AW10: =IF(AH10=1,AV10,0) -> 11691.81 | AX10: =IF(AD10>0,AW10/AD10,0) -> 0.19406077 | AY10: =AD10+AW10 -> 71940 | AZ10: =IF(AY10<M10,1,0) -> 0 | BA10: =Q10*K10 -> 66514.002 | BB10: =RateBelow*MIN(BA10,Ceiling)+AboveCeilingTier1*MIN(MAX(0,BA10-Ceiling),0.1*Ceiling)+AboveCeilingTier2*MIN(MAX(0,BA10-1.1*Ceiling),0.4*Ceiling)+AboveCeilingTier3*MAX(0,BA10-1.5*Ceiling) -> 19731.306 | BC10: =AD10*(1+J10)*K10 -> 66514.002 | BD10: =RateBelow*MIN(BC10,Ceiling)+AboveCeilingTier1*MIN(MAX(0,BC10-Ceiling),0.1*Ceiling)+AboveCeilingTier2*MIN(MAX(0,BC10-1.1*Ceiling),0.4*Ceiling)+AboveCeilingTier3*MAX(0,BC10-1.5*Ceiling) -> 19731.306 | BE10: =AY10*(1+J10)*K10 -> 79421.76 | BF10: =RateBelow*MIN(BE10,Ceiling)+AboveCeilingTier1*MIN(MAX(0,BE10-Ceiling),0.1*Ceiling)+AboveCeilingTier2*MIN(MAX(0,BE10-1.1*Ceiling),0.4*Ceiling)+AboveCeilingTier3*MAX(0,BE10-1.5*Ceiling) -> 19864.889 | BG10: =AC10*K10 -> 0 | BH10: =AC10*J10*K10 -> 0 | BI10: =BD10-BB10 -> 0 | BJ10: =AW10*K10 -> 11691.81 | BK10: =AW10*J10*K10 -> 1215.9482 | BL10: =BF10-BD10 -> 133.58322 | BM10: =IF(AH10=1,AD10*K10,0) -> 60248.19 | BN10: =IF(AH10=1,AD10*PoolPct,0) -> 2409.9276 | BO10: =BN10*K10 -> 2409.9276 | BP10: =BN10*J10*K10 -> 250.63247 | BQ10: =(AD10+BN10)*(1+J10)*K10 -> 69174.562 | BR10: =RateBelow*MIN(BQ10,Ceiling)+AboveCeilingTier1*MIN(MAX(0,BQ10-Ceiling),0.1*Ceiling)+AboveCeilingTier2*MIN(MAX(0,BQ10-1.1*Ceiling),0.4*Ceiling)+AboveCeilingTier3*MAX(0,BQ10-1.5*Ceiling) -> 19758.318 | BS10: =BR10-BD10 -> 27.012354 | BT10: =AD10*(1+J10) -> 66514.002 | BU10: =AY10*(1+J10) -> 79421.76 | BV10: =E10*BU10 -> 714795.84 | BW10: =P10*BU10 -> 436846.86
A11: =ROW()-4 -> 7 | B11: =INDEX(Employees!$A:$A,A11+1) -> E007 | C11: =INDEX(Employees!$A:$Z,MATCH(B11,Employees!$A:$A,0),MATCH("category",Employees!$1:$1,0)) -> Engineering | D11: =INDEX(Employees!$A:$Z,MATCH(B11,Employees!$A:$A,0),MATCH("gender",Employees!$1:$1,0)) -> M | E11: =INDEX(Employees!$A:$Z,MATCH(B11,Employees!$A:$A,0),MATCH("grade",Employees!$1:$1,0)) -> 7 | F11: =INDEX(Employees!$A:$Z,MATCH(B11,Employees!$A:$A,0),MATCH("rating",Employees!$1:$1,0)) -> 5 | G11: =INDEX(Employees!$A:$Z,MATCH(B11,Employees!$A:$A,0),MATCH("hire_date",Employees!$1:$1,0)) -> 44725 | H11: =INDEX(Employees!$A:$Z,MATCH(B11,Employees!$A:$A,0),MATCH("last_change_date",Employees!$1:$1,0)) -> 46113 | I11: =INDEX(Employees!$A:$Z,MATCH(B11,Employees!$A:$A,0),MATCH("base_salary",Employees!$1:$1,0)) -> 47983.14 | J11: =INDEX(Employees!$A:$Z,MATCH(B11,Employees!$A:$A,0),MATCH("bonus_pct",Employees!$1:$1,0))/100 -> 0.1181 | K11: =INDEX(Employees!$A:$Z,MATCH(B11,Employees!$A:$A,0),MATCH("fte",Employees!$1:$1,0)) -> 1 | L11: =IF(ISNA(MATCH(C11&"|"&E11,Bands!$F:$F,0)),0,1) -> 1 | M11: =INDEX(Bands!$C:$C,MATCH(C11&"|"&E11,Bands!$F:$F,0)) -> 41600 | N11: =INDEX(Bands!$D:$D,MATCH(C11&"|"&E11,Bands!$F:$F,0)) -> 49900 | O11: =INDEX(Bands!$E:$E,MATCH(C11&"|"&E11,Bands!$F:$F,0)) -> 58200 | P11: =(EffDate-G11)/365.25 -> 4.7994524 | Q11: =I11*(1+J11) -> 53649.949 | R11: =E11^2 -> 49 | S11: =P11^2 -> 23.034744 | T11: =E11*P11 -> 33.596167 | U11: =E11*Q11 -> 375549.64 | V11: =P11*Q11 -> 257490.38 | W11: =ROUND(Q11,2) -> 53649.95 | X11: =COUNTIFS($C:$C,C11,$W:$W,"<"&W11)+COUNTIFS($C:$C,C11,$W:$W,W11,$B:$B,"<"&B11)+1 -> 7 | Y11: =INDEX(Categories!$AH:$AH,MATCH(C11,Categories!$A:$A,0)) -> 71955.394 | Z11: =IF(AND(D11="F",Q11<Y11,INDEX(Categories!$AI:$AI,MATCH(C11,Categories!$A:$A,0))>0),1,0) -> 0 | AA11: =IF(Z11=1,Y11-Q11,0) -> 0 | AB11: =IF(Z11=1,INDEX(Categories!$AI:$AI,MATCH(C11,Categories!$A:$A,0))*AA11/INDEX(Categories!$AJ:$AJ,MATCH(C11,Categories!$A:$A,0)),0) -> 0 | AC11: =AB11/(1+J11) -> 0 | AD11: =I11+AC11 -> 47983.14 | AE11: =IF(AND(AC11>0,AD11>O11),1,0) -> 0 | AF11: =IF(G11>EffDate,-1,DATEDIF(G11,EffDate,"m")) -> 57 | AG11: =IF(H11>EffDate,-1,DATEDIF(H11,EffDate,"m")) -> 12 | AH11: =IF(AND(AF11>=MinMonthsHire,AG11>=MinMonthsChange),1,0) -> 1 | AI11: =AD11/N11 -> 0.96158597 | AJ11: =MATCH(AI11,Inputs!$B$31:$B$34,1) -> 2 | AK11: =INDEX(Inputs!$C$21:$C$25,MATCH(F11,Inputs!$A$21:$A$25,0)) -> 1.1 | AL11: =INDEX(Inputs!$D$21:$D$25,MATCH(F11,Inputs!$A$21:$A$25,0)) -> 0.02 | AM11: =N11*CompanyTarget*AK11 -> 54890 | AN11: =MAX(0,AM11-AD11) -> 6906.86 | AO11: =IF(AND(ISNUMBER(MaxIncrease),MaxIncrease>0),1,0) -> 1 | AP11: =IF(AO11=1,AD11*MaxIncrease,0) -> 14394.942 | AQ11: =AD11*AL11 -> 959.6628 | AR11: =IF(AK11=0,0,IF(AO11=1,MIN(MAX(AN11,AQ11),AP11),MAX(AN11,AQ11))) -> 6906.86 | AS11: =IF(AD11>=O11,1,0) -> 0 | AT11: =IF(AS11=1,0,AR11) -> 6906.86 | AU11: =MAX(0,O11-AD11) -> 10216.86 | AV11: =IF(ClipAtMax="No",AT11,MIN(AT11,AU11)) -> 6906.86 | AW11: =IF(AH11=1,AV11,0) -> 6906.86 | AX11: =IF(AD11>0,AW11/AD11,0) -> 0.14394348 | AY11: =AD11+AW11 -> 54890 | AZ11: =IF(AY11<M11,1,0) -> 0 | BA11: =Q11*K11 -> 53649.949 | BB11: =RateBelow*MIN(BA11,Ceiling)+AboveCeilingTier1*MIN(MAX(0,BA11-Ceiling),0.1*Ceiling)+AboveCeilingTier2*MIN(MAX(0,BA11-1.1*Ceiling),0.4*Ceiling)+AboveCeilingTier3*MAX(0,BA11-1.5*Ceiling) -> 17248.459 | BC11: =AD11*(1+J11)*K11 -> 53649.949 | BD11: =RateBelow*MIN(BC11,Ceiling)+AboveCeilingTier1*MIN(MAX(0,BC11-Ceiling),0.1*Ceiling)+AboveCeilingTier2*MIN(MAX(0,BC11-1.1*Ceiling),0.4*Ceiling)+AboveCeilingTier3*MAX(0,BC11-1.5*Ceiling) -> 17248.459 | BE11: =AY11*(1+J11)*K11 -> 61372.509 | BF11: =RateBelow*MIN(BE11,Ceiling)+AboveCeilingTier1*MIN(MAX(0,BE11-Ceiling),0.1*Ceiling)+AboveCeilingTier2*MIN(MAX(0,BE11-1.1*Ceiling),0.4*Ceiling)+AboveCeilingTier3*MAX(0,BE11-1.5*Ceiling) -> 19681.947 | BG11: =AC11*K11 -> 0 | BH11: =AC11*J11*K11 -> 0 | BI11: =BD11-BB11 -> 0 | BJ11: =AW11*K11 -> 6906.86 | BK11: =AW11*J11*K11 -> 815.70017 | BL11: =BF11-BD11 -> 2433.4889 | BM11: =IF(AH11=1,AD11*K11,0) -> 47983.14 | BN11: =IF(AH11=1,AD11*PoolPct,0) -> 1919.3256 | BO11: =BN11*K11 -> 1919.3256 | BP11: =BN11*J11*K11 -> 226.67235 | BQ11: =(AD11+BN11)*(1+J11)*K11 -> 55795.947 | BR11: =RateBelow*MIN(BQ11,Ceiling)+AboveCeilingTier1*MIN(MAX(0,BQ11-Ceiling),0.1*Ceiling)+AboveCeilingTier2*MIN(MAX(0,BQ11-1.1*Ceiling),0.4*Ceiling)+AboveCeilingTier3*MAX(0,BQ11-1.5*Ceiling) -> 17938.397 | BS11: =BR11-BD11 -> 689.93834 | BT11: =AD11*(1+J11) -> 53649.949 | BU11: =AY11*(1+J11) -> 61372.509 | BV11: =E11*BU11 -> 429607.56 | BW11: =P11*BU11 -> 294554.44
A12: =ROW()-4 -> 8 | B12: =INDEX(Employees!$A:$A,A12+1) -> E008 | C12: =INDEX(Employees!$A:$Z,MATCH(B12,Employees!$A:$A,0),MATCH("category",Employees!$1:$1,0)) -> Engineering | D12: =INDEX(Employees!$A:$Z,MATCH(B12,Employees!$A:$A,0),MATCH("gender",Employees!$1:$1,0)) -> M | E12: =INDEX(Employees!$A:$Z,MATCH(B12,Employees!$A:$A,0),MATCH("grade",Employees!$1:$1,0)) -> 11 | F12: =INDEX(Employees!$A:$Z,MATCH(B12,Employees!$A:$A,0),MATCH("rating",Employees!$1:$1,0)) -> 2 | G12: =INDEX(Employees!$A:$Z,MATCH(B12,Employees!$A:$A,0),MATCH("hire_date",Employees!$1:$1,0)) -> 44067 | H12: =INDEX(Employees!$A:$Z,MATCH(B12,Employees!$A:$A,0),MATCH("last_change_date",Employees!$1:$1,0)) -> 46113 | I12: =INDEX(Employees!$A:$Z,MATCH(B12,Employees!$A:$A,0),MATCH("base_salary",Employees!$1:$1,0)) -> 79273.59 | J12: =INDEX(Employees!$A:$Z,MATCH(B12,Employees!$A:$A,0),MATCH("bonus_pct",Employees!$1:$1,0))/100 -> 0.0924 | K12: =INDEX(Employees!$A:$Z,MATCH(B12,Employees!$A:$A,0),MATCH("fte",Employees!$1:$1,0)) -> 1 | L12: =IF(ISNA(MATCH(C12&"|"&E12,Bands!$F:$F,0)),0,1) -> 1 | M12: =INDEX(Bands!$C:$C,MATCH(C12&"|"&E12,Bands!$F:$F,0)) -> 68400 | N12: =INDEX(Bands!$D:$D,MATCH(C12&"|"&E12,Bands!$F:$F,0)) -> 85500 | O12: =INDEX(Bands!$E:$E,MATCH(C12&"|"&E12,Bands!$F:$F,0)) -> 102600 | P12: =(EffDate-G12)/365.25 -> 6.6009582 | Q12: =I12*(1+J12) -> 86598.47 | R12: =E12^2 -> 121 | S12: =P12^2 -> 43.57265 | T12: =E12*P12 -> 72.610541 | U12: =E12*Q12 -> 952583.17 | V12: =P12*Q12 -> 571632.88 | W12: =ROUND(Q12,2) -> 86598.47 | X12: =COUNTIFS($C:$C,C12,$W:$W,"<"&W12)+COUNTIFS($C:$C,C12,$W:$W,W12,$B:$B,"<"&B12)+1 -> 37 | Y12: =INDEX(Categories!$AH:$AH,MATCH(C12,Categories!$A:$A,0)) -> 71955.394 | Z12: =IF(AND(D12="F",Q12<Y12,INDEX(Categories!$AI:$AI,MATCH(C12,Categories!$A:$A,0))>0),1,0) -> 0 | AA12: =IF(Z12=1,Y12-Q12,0) -> 0 | AB12: =IF(Z12=1,INDEX(Categories!$AI:$AI,MATCH(C12,Categories!$A:$A,0))*AA12/INDEX(Categories!$AJ:$AJ,MATCH(C12,Categories!$A:$A,0)),0) -> 0 | AC12: =AB12/(1+J12) -> 0 | AD12: =I12+AC12 -> 79273.59 | AE12: =IF(AND(AC12>0,AD12>O12),1,0) -> 0 | AF12: =IF(G12>EffDate,-1,DATEDIF(G12,EffDate,"m")) -> 79 | AG12: =IF(H12>EffDate,-1,DATEDIF(H12,EffDate,"m")) -> 12 | AH12: =IF(AND(AF12>=MinMonthsHire,AG12>=MinMonthsChange),1,0) -> 1 | AI12: =AD12/N12 -> 0.92717649 | AJ12: =MATCH(AI12,Inputs!$B$31:$B$34,1) -> 2 | AK12: =INDEX(Inputs!$C$21:$C$25,MATCH(F12,Inputs!$A$21:$A$25,0)) -> 0.95 | AL12: =INDEX(Inputs!$D$21:$D$25,MATCH(F12,Inputs!$A$21:$A$25,0)) -> 0 | AM12: =N12*CompanyTarget*AK12 -> 81225 | AN12: =MAX(0,AM12-AD12) -> 1951.41 | AO12: =IF(AND(ISNUMBER(MaxIncrease),MaxIncrease>0),1,0) -> 1 | AP12: =IF(AO12=1,AD12*MaxIncrease,0) -> 23782.077 | AQ12: =AD12*AL12 -> 0 | AR12: =IF(AK12=0,0,IF(AO12=1,MIN(MAX(AN12,AQ12),AP12),MAX(AN12,AQ12))) -> 1951.41 | AS12: =IF(AD12>=O12,1,0) -> 0 | AT12: =IF(AS12=1,0,AR12) -> 1951.41 | AU12: =MAX(0,O12-AD12) -> 23326.41 | AV12: =IF(ClipAtMax="No",AT12,MIN(AT12,AU12)) -> 1951.41 | AW12: =IF(AH12=1,AV12,0) -> 1951.41 | AX12: =IF(AD12>0,AW12/AD12,0) -> 0.024616143 | AY12: =AD12+AW12 -> 81225 | AZ12: =IF(AY12<M12,1,0) -> 0 | BA12: =Q12*K12 -> 86598.47 | BB12: =RateBelow*MIN(BA12,Ceiling)+AboveCeilingTier1*MIN(MAX(0,BA12-Ceiling),0.1*Ceiling)+AboveCeilingTier2*MIN(MAX(0,BA12-1.1*Ceiling),0.4*Ceiling)+AboveCeilingTier3*MAX(0,BA12-1.5*Ceiling) -> 19939.527 | BC12: =AD12*(1+J12)*K12 -> 86598.47 | BD12: =RateBelow*MIN(BC12,Ceiling)+AboveCeilingTier1*MIN(MAX(0,BC12-Ceiling),0.1*Ceiling)+AboveCeilingTier2*MIN(MAX(0,BC12-1.1*Ceiling),0.4*Ceiling)+AboveCeilingTier3*MAX(0,BC12-1.5*Ceiling) -> 19939.527 | BE12: =AY12*(1+J12)*K12 -> 88730.19 | BF12: =RateBelow*MIN(BE12,Ceiling)+AboveCeilingTier1*MIN(MAX(0,BE12-Ceiling),0.1*Ceiling)+AboveCeilingTier2*MIN(MAX(0,BE12-1.1*Ceiling),0.4*Ceiling)+AboveCeilingTier3*MAX(0,BE12-1.5*Ceiling) -> 19961.697 | BG12: =AC12*K12 -> 0 | BH12: =AC12*J12*K12 -> 0 | BI12: =BD12-BB12 -> 0 | BJ12: =AW12*K12 -> 1951.41 | BK12: =AW12*J12*K12 -> 180.31028 | BL12: =BF12-BD12 -> 22.169891 | BM12: =IF(AH12=1,AD12*K12,0) -> 79273.59 | BN12: =IF(AH12=1,AD12*PoolPct,0) -> 3170.9436 | BO12: =BN12*K12 -> 3170.9436 | BP12: =BN12*J12*K12 -> 292.99519 | BQ12: =(AD12+BN12)*(1+J12)*K12 -> 90062.409 | BR12: =RateBelow*MIN(BQ12,Ceiling)+AboveCeilingTier1*MIN(MAX(0,BQ12-Ceiling),0.1*Ceiling)+AboveCeilingTier2*MIN(MAX(0,BQ12-1.1*Ceiling),0.4*Ceiling)+AboveCeilingTier3*MAX(0,BQ12-1.5*Ceiling) -> 19975.552 | BS12: =BR12-BD12 -> 36.024963 | BT12: =AD12*(1+J12) -> 86598.47 | BU12: =AY12*(1+J12) -> 88730.19 | BV12: =E12*BU12 -> 976032.09 | BW12: =P12*BU12 -> 585704.28
A13: =ROW()-4 -> 9 | B13: =INDEX(Employees!$A:$A,A13+1) -> E009 | C13: =INDEX(Employees!$A:$Z,MATCH(B13,Employees!$A:$A,0),MATCH("category",Employees!$1:$1,0)) -> Engineering | D13: =INDEX(Employees!$A:$Z,MATCH(B13,Employees!$A:$A,0),MATCH("gender",Employees!$1:$1,0)) -> M | E13: =INDEX(Employees!$A:$Z,MATCH(B13,Employees!$A:$A,0),MATCH("grade",Employees!$1:$1,0)) -> 8 | F13: =INDEX(Employees!$A:$Z,MATCH(B13,Employees!$A:$A,0),MATCH("rating",Employees!$1:$1,0)) -> 3 | G13: =INDEX(Employees!$A:$Z,MATCH(B13,Employees!$A:$A,0),MATCH("hire_date",Employees!$1:$1,0)) -> 44323 | H13: =INDEX(Employees!$A:$Z,MATCH(B13,Employees!$A:$A,0),MATCH("last_change_date",Employees!$1:$1,0)) -> 46113 | I13: =INDEX(Employees!$A:$Z,MATCH(B13,Employees!$A:$A,0),MATCH("base_salary",Employees!$1:$1,0)) -> 56597.91 | J13: =INDEX(Employees!$A:$Z,MATCH(B13,Employees!$A:$A,0),MATCH("bonus_pct",Employees!$1:$1,0))/100 -> 0.1073 | K13: =INDEX(Employees!$A:$Z,MATCH(B13,Employees!$A:$A,0),MATCH("fte",Employees!$1:$1,0)) -> 1 | L13: =IF(ISNA(MATCH(C13&"|"&E13,Bands!$F:$F,0)),0,1) -> 1 | M13: =INDEX(Bands!$C:$C,MATCH(C13&"|"&E13,Bands!$F:$F,0)) -> 47700 | N13: =INDEX(Bands!$D:$D,MATCH(C13&"|"&E13,Bands!$F:$F,0)) -> 57200 | O13: =INDEX(Bands!$E:$E,MATCH(C13&"|"&E13,Bands!$F:$F,0)) -> 66800 | P13: =(EffDate-G13)/365.25 -> 5.9000684 | Q13: =I13*(1+J13) -> 62670.866 | R13: =E13^2 -> 64 | S13: =P13^2 -> 34.810808 | T13: =E13*P13 -> 47.200548 | U13: =E13*Q13 -> 501366.93 | V13: =P13*Q13 -> 369762.4 | W13: =ROUND(Q13,2) -> 62670.87 | X13: =COUNTIFS($C:$C,C13,$W:$W,"<"&W13)+COUNTIFS($C:$C,C13,$W:$W,W13,$B:$B,"<"&B13)+1 -> 15 | Y13: =INDEX(Categories!$AH:$AH,MATCH(C13,Categories!$A:$A,0)) -> 71955.394 | Z13: =IF(AND(D13="F",Q13<Y13,INDEX(Categories!$AI:$AI,MATCH(C13,Categories!$A:$A,0))>0),1,0) -> 0 | AA13: =IF(Z13=1,Y13-Q13,0) -> 0 | AB13: =IF(Z13=1,INDEX(Categories!$AI:$AI,MATCH(C13,Categories!$A:$A,0))*AA13/INDEX(Categories!$AJ:$AJ,MATCH(C13,Categories!$A:$A,0)),0) -> 0 | AC13: =AB13/(1+J13) -> 0 | AD13: =I13+AC13 -> 56597.91 | AE13: =IF(AND(AC13>0,AD13>O13),1,0) -> 0 | AF13: =IF(G13>EffDate,-1,DATEDIF(G13,EffDate,"m")) -> 70 | AG13: =IF(H13>EffDate,-1,DATEDIF(H13,EffDate,"m")) -> 12 | AH13: =IF(AND(AF13>=MinMonthsHire,AG13>=MinMonthsChange),1,0) -> 1 | AI13: =AD13/N13 -> 0.98947395 | AJ13: =MATCH(AI13,Inputs!$B$31:$B$34,1) -> 2 | AK13: =INDEX(Inputs!$C$21:$C$25,MATCH(F13,Inputs!$A$21:$A$25,0)) -> 1 | AL13: =INDEX(Inputs!$D$21:$D$25,MATCH(F13,Inputs!$A$21:$A$25,0)) -> 0 | AM13: =N13*CompanyTarget*AK13 -> 57200 | AN13: =MAX(0,AM13-AD13) -> 602.09 | AO13: =IF(AND(ISNUMBER(MaxIncrease),MaxIncrease>0),1,0) -> 1 | AP13: =IF(AO13=1,AD13*MaxIncrease,0) -> 16979.373 | AQ13: =AD13*AL13 -> 0 | AR13: =IF(AK13=0,0,IF(AO13=1,MIN(MAX(AN13,AQ13),AP13),MAX(AN13,AQ13))) -> 602.09 | AS13: =IF(AD13>=O13,1,0) -> 0 | AT13: =IF(AS13=1,0,AR13) -> 602.09 | AU13: =MAX(0,O13-AD13) -> 10202.09 | AV13: =IF(ClipAtMax="No",AT13,MIN(AT13,AU13)) -> 602.09 | AW13: =IF(AH13=1,AV13,0) -> 602.09 | AX13: =IF(AD13>0,AW13/AD13,0) -> 0.010638025 | AY13: =AD13+AW13 -> 57200 | AZ13: =IF(AY13<M13,1,0) -> 0 | BA13: =Q13*K13 -> 62670.866 | BB13: =RateBelow*MIN(BA13,Ceiling)+AboveCeilingTier1*MIN(MAX(0,BA13-Ceiling),0.1*Ceiling)+AboveCeilingTier2*MIN(MAX(0,BA13-1.1*Ceiling),0.4*Ceiling)+AboveCeilingTier3*MAX(0,BA13-1.5*Ceiling) -> 19694.412 | BC13: =AD13*(1+J13)*K13 -> 62670.866 | BD13: =RateBelow*MIN(BC13,Ceiling)+AboveCeilingTier1*MIN(MAX(0,BC13-Ceiling),0.1*Ceiling)+AboveCeilingTier2*MIN(MAX(0,BC13-1.1*Ceiling),0.4*Ceiling)+AboveCeilingTier3*MAX(0,BC13-1.5*Ceiling) -> 19694.412 | BE13: =AY13*(1+J13)*K13 -> 63337.56 | BF13: =RateBelow*MIN(BE13,Ceiling)+AboveCeilingTier1*MIN(MAX(0,BE13-Ceiling),0.1*Ceiling)+AboveCeilingTier2*MIN(MAX(0,BE13-1.1*Ceiling),0.4*Ceiling)+AboveCeilingTier3*MAX(0,BE13-1.5*Ceiling) -> 19700.812 | BG13: =AC13*K13 -> 0 | BH13: =AC13*J13*K13 -> 0 | BI13: =BD13-BB13 -> 0 | BJ13: =AW13*K13 -> 602.09 | BK13: =AW13*J13*K13 -> 64.604257 | BL13: =BF13-BD13 -> 6.4002649 | BM13: =IF(AH13=1,AD13*K13,0) -> 56597.91 | BN13: =IF(AH13=1,AD13*PoolPct,0) -> 2263.9164 | BO13: =BN13*K13 -> 2263.9164 | BP13: =BN13*J13*K13 -> 242.91823 | BQ13: =(AD13+BN13)*(1+J13)*K13 -> 65177.7 | BR13: =RateBelow*MIN(BQ13,Ceiling)+AboveCeilingTier1*MIN(MAX(0,BQ13-Ceiling),0.1*Ceiling)+AboveCeilingTier2*MIN(MAX(0,BQ13-1.1*Ceiling),0.4*Ceiling)+AboveCeilingTier3*MAX(0,BQ13-1.5*Ceiling) -> 19718.477 | BS13: =BR13-BD13 -> 24.065612 | BT13: =AD13*(1+J13) -> 62670.866 | BU13: =AY13*(1+J13) -> 63337.56 | BV13: =E13*BU13 -> 506700.48 | BW13: =P13*BU13 -> 373695.94
